[32mINFO    [0m pytest_operator.plugin:plugin.py:937 Model status:

Model    Controller     Cloud/Region         Version  SLA          Timestamp
testing  concierge-lxd  localhost/localhost  3.6.5    unsupported  01:46:12Z

App                       Version  Status  Scale  Charm                     Channel        Rev  Exposed  Message
data-integrator                    error       2  data-integrator           latest/edge    145  no       hook failed: "secret-changed"
pgbouncer                 1.21.0   active      2  pgbouncer                                  0  no       
postgresql                14.17    active      2  postgresql                14/edge        605  no       
self-signed-certificates           active      1  self-signed-certificates  latest/stable  264  no       

Unit                         Workload     Agent      Machine  Public address  Ports     Message
data-integrator/0*           active       executing  0        10.169.247.50             
  pgbouncer/0*               active       executing           10.169.247.50   6432/tcp  
data-integrator/1            error        idle       1        10.169.247.165            hook failed: "secret-changed"
  pgbouncer/1                active       idle                10.169.247.165  6432/tcp  
postgresql/0*                active       executing  3        10.169.247.95   5432/tcp  Primary (degraded)
postgresql/1                 maintenance  executing  4        10.169.247.152            (install) installing PostgreSQL
self-signed-certificates/0*  active       idle       2        10.169.247.223            

Machine  State    Address         Inst id        Base          AZ  Message
0        started  10.169.247.50   juju-ebb6fc-0  ubuntu@24.04      Running
1        started  10.169.247.165  juju-ebb6fc-1  ubuntu@24.04      Running
2        started  10.169.247.223  juju-ebb6fc-2  ubuntu@22.04      Running
3        started  10.169.247.95   juju-ebb6fc-3  ubuntu@22.04      Running
4        started  10.169.247.152  juju-ebb6fc-4  ubuntu@22.04      Running

[32mINFO    [0m pytest_operator.plugin:plugin.py:943 Juju error logs:

machine-0: 01:42:48 ERROR juju.worker.dependency "lxd-container-provisioner" manifold worker returned unexpected error: container types not yet available
machine-0: 01:42:48 ERROR juju.worker.dependency "kvm-container-provisioner" manifold worker returned unexpected error: container types not yet available
unit-data-integrator-0: 01:42:49 ERROR juju.worker.meterstatus error running "meter-status-changed": charm missing from disk
unit-pgbouncer-0: 01:42:52 ERROR juju.worker.meterstatus error running "meter-status-changed": charm missing from disk
machine-1: 01:43:18 ERROR juju.worker.dependency "kvm-container-provisioner" manifold worker returned unexpected error: container types not yet available
machine-1: 01:43:18 ERROR juju.worker.dependency "lxd-container-provisioner" manifold worker returned unexpected error: container types not yet available
unit-data-integrator-1: 01:43:19 ERROR juju.worker.meterstatus error running "meter-status-changed": charm missing from disk
unit-pgbouncer-1: 01:43:24 ERROR juju.worker.meterstatus error running "meter-status-changed": charm missing from disk
machine-3: 01:44:08 ERROR juju.worker.dependency "kvm-container-provisioner" manifold worker returned unexpected error: container types not yet available
machine-3: 01:44:09 ERROR juju.worker.dependency "lxd-container-provisioner" manifold worker returned unexpected error: container types not yet available
unit-postgresql-0: 01:44:09 ERROR juju.worker.meterstatus error running "meter-status-changed": charm missing from disk
machine-2: 01:45:13 ERROR juju.worker.dependency "kvm-container-provisioner" manifold worker returned unexpected error: container types not yet available
machine-2: 01:45:13 ERROR juju.worker.dependency "lxd-container-provisioner" manifold worker returned unexpected error: container types not yet available
unit-self-signed-certificates-0: 01:45:13 ERROR juju.worker.meterstatus error running "meter-status-changed": charm missing from disk
unit-postgresql-0: 01:45:23 ERROR unit.postgresql/0.juju-log Unable to get the state of the cluster
Traceback (most recent call last):
  File "/var/lib/juju/agents/unit-postgresql-0/charm/venv/lib/python3.10/site-packages/urllib3/connection.py", line 198, in _new_conn
    sock = connection.create_connection(
  File "/var/lib/juju/agents/unit-postgresql-0/charm/venv/lib/python3.10/site-packages/urllib3/util/connection.py", line 85, in create_connection
    raise err
  File "/var/lib/juju/agents/unit-postgresql-0/charm/venv/lib/python3.10/site-packages/urllib3/util/connection.py", line 73, in create_connection
    sock.connect(sa)
ConnectionRefusedError: [Errno 111] Connection refused

The above exception was the direct cause of the following exception:

Traceback (most recent call last):
  File "/var/lib/juju/agents/unit-postgresql-0/charm/venv/lib/python3.10/site-packages/urllib3/connectionpool.py", line 787, in urlopen
    response = self._make_request(
  File "/var/lib/juju/agents/unit-postgresql-0/charm/venv/lib/python3.10/site-packages/urllib3/connectionpool.py", line 493, in _make_request
    conn.request(
  File "/var/lib/juju/agents/unit-postgresql-0/charm/venv/lib/python3.10/site-packages/urllib3/connection.py", line 445, in request
    self.endheaders()
  File "/usr/lib/python3.10/http/client.py", line 1278, in endheaders
    self._send_output(message_body, encode_chunked=encode_chunked)
  File "/usr/lib/python3.10/http/client.py", line 1038, in _send_output
    self.send(msg)
  File "/usr/lib/python3.10/http/client.py", line 976, in send
    self.connect()
  File "/var/lib/juju/agents/unit-postgresql-0/charm/venv/lib/python3.10/site-packages/urllib3/connection.py", line 276, in connect
    self.sock = self._new_conn()
  File "/var/lib/juju/agents/unit-postgresql-0/charm/venv/lib/python3.10/site-packages/urllib3/connection.py", line 213, in _new_conn
    raise NewConnectionError(
urllib3.exceptions.NewConnectionError: <urllib3.connection.HTTPConnection object at 0x7f3e15741de0>: Failed to establish a new connection: [Errno 111] Connection refused

The above exception was the direct cause of the following exception:

Traceback (most recent call last):
  File "/var/lib/juju/agents/unit-postgresql-0/charm/venv/lib/python3.10/site-packages/requests/adapters.py", line 667, in send
    resp = conn.urlopen(
  File "/var/lib/juju/agents/unit-postgresql-0/charm/venv/lib/python3.10/site-packages/urllib3/connectionpool.py", line 841, in urlopen
    retries = retries.increment(
  File "/var/lib/juju/agents/unit-postgresql-0/charm/venv/lib/python3.10/site-packages/urllib3/util/retry.py", line 519, in increment
    raise MaxRetryError(_pool, url, reason) from reason  # type: ignore[arg-type]
urllib3.exceptions.MaxRetryError: HTTPConnectionPool(host='10.169.247.95', port=8008): Max retries exceeded with url: /cluster (Caused by NewConnectionError('<urllib3.connection.HTTPConnection object at 0x7f3e15741de0>: Failed to establish a new connection: [Errno 111] Connection refused'))

During handling of the above exception, another exception occurred:

Traceback (most recent call last):
  File "/var/lib/juju/agents/unit-postgresql-0/charm/src/cluster.py", line 563, in are_replicas_up
    response = requests.get(
  File "/var/lib/juju/agents/unit-postgresql-0/charm/venv/lib/python3.10/site-packages/requests/api.py", line 73, in get
    return request("get", url, params=params, **kwargs)
  File "/var/lib/juju/agents/unit-postgresql-0/charm/venv/lib/python3.10/site-packages/requests/api.py", line 59, in request
    return session.request(method=method, url=url, **kwargs)
  File "/var/lib/juju/agents/unit-postgresql-0/charm/venv/lib/python3.10/site-packages/requests/sessions.py", line 589, in request
    resp = self.send(prep, **send_kwargs)
  File "/var/lib/juju/agents/unit-postgresql-0/charm/venv/lib/python3.10/site-packages/requests/sessions.py", line 703, in send
    r = adapter.send(request, **kwargs)
  File "/var/lib/juju/agents/unit-postgresql-0/charm/venv/lib/python3.10/site-packages/requests/adapters.py", line 700, in send
    raise ConnectionError(e, request=request)
requests.exceptions.ConnectionError: HTTPConnectionPool(host='10.169.247.95', port=8008): Max retries exceeded with url: /cluster (Caused by NewConnectionError('<urllib3.connection.HTTPConnection object at 0x7f3e15741de0>: Failed to establish a new connection: [Errno 111] Connection refused'))
machine-4: 01:45:30 ERROR juju.worker.dependency "lxd-container-provisioner" manifold worker returned unexpected error: container types not yet available
machine-4: 01:45:30 ERROR juju.worker.dependency "kvm-container-provisioner" manifold worker returned unexpected error: container types not yet available
unit-postgresql-1: 01:45:30 ERROR juju.worker.meterstatus error running "meter-status-changed": charm missing from disk
unit-data-integrator-1: 01:46:11 ERROR unit.data-integrator/1.juju-log Uncaught exception while in charm code:
Traceback (most recent call last):
  File "/var/lib/juju/agents/unit-data-integrator-1/charm/src/charm.py", line 516, in <module>
    main(IntegratorCharm)
  File "/var/lib/juju/agents/unit-data-integrator-1/charm/venv/lib/python3.12/site-packages/ops/__init__.py", line 347, in __call__
    return _main.main(charm_class=charm_class, use_juju_for_storage=use_juju_for_storage)
           ^^^^^^^^^^^^^^^^^^^^^^^^^^^^^^^^^^^^^^^^^^^^^^^^^^^^^^^^^^^^^^^^^^^^^^^^^^^^^^
  File "/var/lib/juju/agents/unit-data-integrator-1/charm/venv/lib/python3.12/site-packages/ops/_main.py", line 565, in main
    manager.run()
  File "/var/lib/juju/agents/unit-data-integrator-1/charm/venv/lib/python3.12/site-packages/ops/_main.py", line 550, in run
    self._emit()
  File "/var/lib/juju/agents/unit-data-integrator-1/charm/venv/lib/python3.12/site-packages/ops/_main.py", line 502, in _emit
    self._emit_charm_event(self.dispatcher.event_name)
  File "/var/lib/juju/agents/unit-data-integrator-1/charm/venv/lib/python3.12/site-packages/ops/_main.py", line 537, in _emit_charm_event
    event_to_emit.emit(*args, **kwargs)
  File "/var/lib/juju/agents/unit-data-integrator-1/charm/venv/lib/python3.12/site-packages/ops/framework.py", line 348, in emit
    framework._emit(event)
  File "/var/lib/juju/agents/unit-data-integrator-1/charm/venv/lib/python3.12/site-packages/ops/framework.py", line 907, in _emit
    self._reemit(event_path)
  File "/var/lib/juju/agents/unit-data-integrator-1/charm/venv/lib/python3.12/site-packages/ops/framework.py", line 997, in _reemit
    custom_handler(event)
  File "/var/lib/juju/agents/unit-data-integrator-1/charm/lib/charms/data_platform_libs/v0/data_interfaces.py", line 4108, in _on_secret_changed_event
    getattr(self.on, "etcd_ready").emit(relation, app=relation.app, unit=remote_unit)
  File "/var/lib/juju/agents/unit-data-integrator-1/charm/venv/lib/python3.12/site-packages/ops/framework.py", line 348, in emit
    framework._emit(event)
  File "/var/lib/juju/agents/unit-data-integrator-1/charm/venv/lib/python3.12/site-packages/ops/framework.py", line 907, in _emit
    self._reemit(event_path)
  File "/var/lib/juju/agents/unit-data-integrator-1/charm/venv/lib/python3.12/site-packages/ops/framework.py", line 997, in _reemit
    custom_handler(event)
  File "/var/lib/juju/agents/unit-data-integrator-1/charm/src/charm.py", line 301, in _on_etcd_ready
    self._update_relation_status(event, Statuses.ACTIVE.name)
  File "/var/lib/juju/agents/unit-data-integrator-1/charm/src/charm.py", line 305, in _update_relation_status
    self.set_secret("app", event.relation.name, status)
  File "/var/lib/juju/agents/unit-data-integrator-1/charm/src/charm.py", line 510, in set_secret
    self.app_peer_data.update({key: value})
  File "/var/lib/juju/agents/unit-data-integrator-1/charm/venv/lib/python3.12/site-packages/ops/model.py", line 1986, in update
    self._validate_write(changes)  # always check permissions
    ^^^^^^^^^^^^^^^^^^^^^^^^^^^^^
  File "/var/lib/juju/agents/unit-data-integrator-1/charm/venv/lib/python3.12/site-packages/ops/model.py", line 1903, in _validate_write
    self._validate_write_access()
  File "/var/lib/juju/agents/unit-data-integrator-1/charm/venv/lib/python3.12/site-packages/ops/model.py", line 1931, in _validate_write_access
    raise RelationDataAccessError(
ops.model.RelationDataAccessError: data-integrator/1 is not leader and cannot write application data.
unit-data-integrator-1: 01:46:11 ERROR juju.worker.uniter.operation hook "secret-changed" (via hook dispatching script: dispatch) failed: exit status 1

[32mINFO    [0m pytest_operator.plugin:plugin.py:1025 Forgetting model main...