[32mINFO    [0m pytest_operator.plugin:plugin.py:936 Model status:

Model    Controller     Cloud/Region         Version  SLA          Timestamp
testing  concierge-lxd  localhost/localhost  3.6.2    unsupported  02:11:08Z

App                  Version  Status  Scale  Charm                Channel      Rev  Exposed  Message
another-application           active      1  postgresql-test-app  latest/edge  365  no       
another-pgbouncer    1.21.0   active      2  pgbouncer                           1  no       
another-postgresql   14.15    active      2  postgresql           14/edge      567  no       
pgbouncer            1.21.0   active      2  pgbouncer                           0  no       
postgresql           14.15    active      2  postgresql           14/edge      567  no       
postgresql-test-app           active      2  postgresql-test-app  latest/edge  365  no       received database credentials of the first database

Unit                    Workload  Agent  Machine  Public address  Ports     Message
another-application/0*  active    idle   4        10.104.191.109            
another-postgresql/0*   active    idle   5        10.104.191.127  5432/tcp  Primary
another-postgresql/1    active    idle   6        10.104.191.52   5432/tcp  
postgresql-test-app/1*  active    idle   3        10.104.191.76             received database credentials of the first database
  another-pgbouncer/2*  active    idle            10.104.191.76             
  pgbouncer/4*          active    idle            10.104.191.76             
postgresql-test-app/2   active    idle   7        10.104.191.211            received database credentials of the first database
  another-pgbouncer/9   active    idle            10.104.191.211            
  pgbouncer/9           active    idle            10.104.191.211            
postgresql/0*           active    idle   1        10.104.191.205  5432/tcp  Primary
postgresql/1            active    idle   2        10.104.191.215  5432/tcp  

Machine  State    Address         Inst id        Base          AZ  Message
1        started  10.104.191.205  juju-8030da-1  ubuntu@22.04      Running
2        started  10.104.191.215  juju-8030da-2  ubuntu@22.04      Running
3        started  10.104.191.76   juju-8030da-3  ubuntu@22.04      Running
4        started  10.104.191.109  juju-8030da-4  ubuntu@22.04      Running
5        started  10.104.191.127  juju-8030da-5  ubuntu@22.04      Running
6        started  10.104.191.52   juju-8030da-6  ubuntu@22.04      Running
7        started  10.104.191.211  juju-8030da-7  ubuntu@22.04      Running

[32mINFO    [0m pytest_operator.plugin:plugin.py:942 Juju error logs:

machine-0: 01:42:53 ERROR juju.worker.dependency "kvm-container-provisioner" manifold worker returned unexpected error: container types not yet available
machine-0: 01:42:53 ERROR juju.worker.dependency "lxd-container-provisioner" manifold worker returned unexpected error: container types not yet available
unit-postgresql-test-app-0: 01:42:53 ERROR juju.worker.meterstatus error running "meter-status-changed": charm missing from disk
machine-1: 01:44:05 ERROR juju.worker.dependency "kvm-container-provisioner" manifold worker returned unexpected error: container types not yet available
machine-1: 01:44:05 ERROR juju.worker.dependency "lxd-container-provisioner" manifold worker returned unexpected error: container types not yet available
unit-postgresql-0: 01:44:05 ERROR juju.worker.meterstatus error running "meter-status-changed": charm missing from disk
machine-2: 01:44:14 ERROR juju.worker.dependency "lxd-container-provisioner" manifold worker returned unexpected error: container types not yet available
machine-2: 01:44:14 ERROR juju.worker.dependency "kvm-container-provisioner" manifold worker returned unexpected error: container types not yet available
unit-postgresql-1: 01:44:14 ERROR juju.worker.meterstatus error running "meter-status-changed": charm missing from disk
unit-postgresql-0: 01:44:57 ERROR unit.postgresql/0.juju-log Unable to get the state of the cluster
Traceback (most recent call last):
  File "/var/lib/juju/agents/unit-postgresql-0/charm/venv/lib/python3.10/site-packages/urllib3/connection.py", line 198, in _new_conn
    sock = connection.create_connection(
  File "/var/lib/juju/agents/unit-postgresql-0/charm/venv/lib/python3.10/site-packages/urllib3/util/connection.py", line 85, in create_connection
    raise err
  File "/var/lib/juju/agents/unit-postgresql-0/charm/venv/lib/python3.10/site-packages/urllib3/util/connection.py", line 73, in create_connection
    sock.connect(sa)
ConnectionRefusedError: [Errno 111] Connection refused

The above exception was the direct cause of the following exception:

Traceback (most recent call last):
  File "/var/lib/juju/agents/unit-postgresql-0/charm/venv/lib/python3.10/site-packages/urllib3/connectionpool.py", line 787, in urlopen
    response = self._make_request(
  File "/var/lib/juju/agents/unit-postgresql-0/charm/venv/lib/python3.10/site-packages/urllib3/connectionpool.py", line 493, in _make_request
    conn.request(
  File "/var/lib/juju/agents/unit-postgresql-0/charm/venv/lib/python3.10/site-packages/urllib3/connection.py", line 445, in request
    self.endheaders()
  File "/usr/lib/python3.10/http/client.py", line 1278, in endheaders
    self._send_output(message_body, encode_chunked=encode_chunked)
  File "/usr/lib/python3.10/http/client.py", line 1038, in _send_output
    self.send(msg)
  File "/usr/lib/python3.10/http/client.py", line 976, in send
    self.connect()
  File "/var/lib/juju/agents/unit-postgresql-0/charm/venv/lib/python3.10/site-packages/urllib3/connection.py", line 276, in connect
    self.sock = self._new_conn()
  File "/var/lib/juju/agents/unit-postgresql-0/charm/venv/lib/python3.10/site-packages/urllib3/connection.py", line 213, in _new_conn
    raise NewConnectionError(
urllib3.exceptions.NewConnectionError: <urllib3.connection.HTTPConnection object at 0x7ff5227d8130>: Failed to establish a new connection: [Errno 111] Connection refused

The above exception was the direct cause of the following exception:

Traceback (most recent call last):
  File "/var/lib/juju/agents/unit-postgresql-0/charm/venv/lib/python3.10/site-packages/requests/adapters.py", line 667, in send
    resp = conn.urlopen(
  File "/var/lib/juju/agents/unit-postgresql-0/charm/venv/lib/python3.10/site-packages/urllib3/connectionpool.py", line 841, in urlopen
    retries = retries.increment(
  File "/var/lib/juju/agents/unit-postgresql-0/charm/venv/lib/python3.10/site-packages/urllib3/util/retry.py", line 519, in increment
    raise MaxRetryError(_pool, url, reason) from reason  # type: ignore[arg-type]
urllib3.exceptions.MaxRetryError: HTTPConnectionPool(host='10.104.191.205', port=8008): Max retries exceeded with url: /cluster (Caused by NewConnectionError('<urllib3.connection.HTTPConnection object at 0x7ff5227d8130>: Failed to establish a new connection: [Errno 111] Connection refused'))

During handling of the above exception, another exception occurred:

Traceback (most recent call last):
  File "/var/lib/juju/agents/unit-postgresql-0/charm/src/cluster.py", line 552, in are_replicas_up
    response = requests.get(
  File "/var/lib/juju/agents/unit-postgresql-0/charm/venv/lib/python3.10/site-packages/requests/api.py", line 73, in get
    return request("get", url, params=params, **kwargs)
  File "/var/lib/juju/agents/unit-postgresql-0/charm/venv/lib/python3.10/site-packages/requests/api.py", line 59, in request
    return session.request(method=method, url=url, **kwargs)
  File "/var/lib/juju/agents/unit-postgresql-0/charm/venv/lib/python3.10/site-packages/requests/sessions.py", line 589, in request
    resp = self.send(prep, **send_kwargs)
  File "/var/lib/juju/agents/unit-postgresql-0/charm/venv/lib/python3.10/site-packages/requests/sessions.py", line 703, in send
    r = adapter.send(request, **kwargs)
  File "/var/lib/juju/agents/unit-postgresql-0/charm/venv/lib/python3.10/site-packages/requests/adapters.py", line 700, in send
    raise ConnectionError(e, request=request)
requests.exceptions.ConnectionError: HTTPConnectionPool(host='10.104.191.205', port=8008): Max retries exceeded with url: /cluster (Caused by NewConnectionError('<urllib3.connection.HTTPConnection object at 0x7ff5227d8130>: Failed to establish a new connection: [Errno 111] Connection refused'))
unit-postgresql-0: 01:45:07 ERROR unit.postgresql/0.juju-log Failed to list PostgreSQL database users: could not translate host name "None" to address: Temporary failure in name resolution

unit-pgbouncer-0: 01:50:49 ERROR juju.worker.meterstatus error running "meter-status-changed": charm missing from disk
machine-3: 01:52:43 ERROR juju.worker.dependency "lxd-container-provisioner" manifold worker returned unexpected error: container types not yet available
machine-3: 01:52:43 ERROR juju.worker.dependency "kvm-container-provisioner" manifold worker returned unexpected error: container types not yet available
unit-postgresql-test-app-1: 01:52:43 ERROR juju.worker.meterstatus error running "meter-status-changed": charm missing from disk
unit-pgbouncer-1: 01:52:45 ERROR juju.worker.meterstatus error running "meter-status-changed": exit status 1
machine-4: 01:54:27 ERROR juju.worker.dependency "kvm-container-provisioner" manifold worker returned unexpected error: container types not yet available
machine-4: 01:54:27 ERROR juju.worker.dependency "lxd-container-provisioner" manifold worker returned unexpected error: container types not yet available
unit-another-application-0: 01:54:27 ERROR juju.worker.meterstatus error running "meter-status-changed": charm missing from disk
machine-5: 01:56:09 ERROR juju.worker.dependency "lxd-container-provisioner" manifold worker returned unexpected error: container types not yet available
machine-5: 01:56:09 ERROR juju.worker.dependency "kvm-container-provisioner" manifold worker returned unexpected error: container types not yet available
unit-another-postgresql-0: 01:56:09 ERROR juju.worker.meterstatus error running "meter-status-changed": charm missing from disk
machine-6: 01:56:20 ERROR juju.worker.dependency "kvm-container-provisioner" manifold worker returned unexpected error: container types not yet available
machine-6: 01:56:20 ERROR juju.worker.dependency "lxd-container-provisioner" manifold worker returned unexpected error: container types not yet available
unit-another-postgresql-1: 01:56:20 ERROR juju.worker.meterstatus error running "meter-status-changed": charm missing from disk
unit-another-postgresql-0: 01:57:07 ERROR unit.another-postgresql/0.juju-log Unable to get the state of the cluster
Traceback (most recent call last):
  File "/var/lib/juju/agents/unit-another-postgresql-0/charm/venv/lib/python3.10/site-packages/urllib3/connection.py", line 198, in _new_conn
    sock = connection.create_connection(
  File "/var/lib/juju/agents/unit-another-postgresql-0/charm/venv/lib/python3.10/site-packages/urllib3/util/connection.py", line 85, in create_connection
    raise err
  File "/var/lib/juju/agents/unit-another-postgresql-0/charm/venv/lib/python3.10/site-packages/urllib3/util/connection.py", line 73, in create_connection
    sock.connect(sa)
ConnectionRefusedError: [Errno 111] Connection refused

The above exception was the direct cause of the following exception:

Traceback (most recent call last):
  File "/var/lib/juju/agents/unit-another-postgresql-0/charm/venv/lib/python3.10/site-packages/urllib3/connectionpool.py", line 787, in urlopen
    response = self._make_request(
  File "/var/lib/juju/agents/unit-another-postgresql-0/charm/venv/lib/python3.10/site-packages/urllib3/connectionpool.py", line 493, in _make_request
    conn.request(
  File "/var/lib/juju/agents/unit-another-postgresql-0/charm/venv/lib/python3.10/site-packages/urllib3/connection.py", line 445, in request
    self.endheaders()
  File "/usr/lib/python3.10/http/client.py", line 1278, in endheaders
    self._send_output(message_body, encode_chunked=encode_chunked)
  File "/usr/lib/python3.10/http/client.py", line 1038, in _send_output
    self.send(msg)
  File "/usr/lib/python3.10/http/client.py", line 976, in send
    self.connect()
  File "/var/lib/juju/agents/unit-another-postgresql-0/charm/venv/lib/python3.10/site-packages/urllib3/connection.py", line 276, in connect
    self.sock = self._new_conn()
  File "/var/lib/juju/agents/unit-another-postgresql-0/charm/venv/lib/python3.10/site-packages/urllib3/connection.py", line 213, in _new_conn
    raise NewConnectionError(
urllib3.exceptions.NewConnectionError: <urllib3.connection.HTTPConnection object at 0x7f82824e4130>: Failed to establish a new connection: [Errno 111] Connection refused

The above exception was the direct cause of the following exception:

Traceback (most recent call last):
  File "/var/lib/juju/agents/unit-another-postgresql-0/charm/venv/lib/python3.10/site-packages/requests/adapters.py", line 667, in send
    resp = conn.urlopen(
  File "/var/lib/juju/agents/unit-another-postgresql-0/charm/venv/lib/python3.10/site-packages/urllib3/connectionpool.py", line 841, in urlopen
    retries = retries.increment(
  File "/var/lib/juju/agents/unit-another-postgresql-0/charm/venv/lib/python3.10/site-packages/urllib3/util/retry.py", line 519, in increment
    raise MaxRetryError(_pool, url, reason) from reason  # type: ignore[arg-type]
urllib3.exceptions.MaxRetryError: HTTPConnectionPool(host='10.104.191.127', port=8008): Max retries exceeded with url: /cluster (Caused by NewConnectionError('<urllib3.connection.HTTPConnection object at 0x7f82824e4130>: Failed to establish a new connection: [Errno 111] Connection refused'))

During handling of the above exception, another exception occurred:

Traceback (most recent call last):
  File "/var/lib/juju/agents/unit-another-postgresql-0/charm/src/cluster.py", line 552, in are_replicas_up
    response = requests.get(
  File "/var/lib/juju/agents/unit-another-postgresql-0/charm/venv/lib/python3.10/site-packages/requests/api.py", line 73, in get
    return request("get", url, params=params, **kwargs)
  File "/var/lib/juju/agents/unit-another-postgresql-0/charm/venv/lib/python3.10/site-packages/requests/api.py", line 59, in request
    return session.request(method=method, url=url, **kwargs)
  File "/var/lib/juju/agents/unit-another-postgresql-0/charm/venv/lib/python3.10/site-packages/requests/sessions.py", line 589, in request
    resp = self.send(prep, **send_kwargs)
  File "/var/lib/juju/agents/unit-another-postgresql-0/charm/venv/lib/python3.10/site-packages/requests/sessions.py", line 703, in send
    r = adapter.send(request, **kwargs)
  File "/var/lib/juju/agents/unit-another-postgresql-0/charm/venv/lib/python3.10/site-packages/requests/adapters.py", line 700, in send
    raise ConnectionError(e, request=request)
requests.exceptions.ConnectionError: HTTPConnectionPool(host='10.104.191.127', port=8008): Max retries exceeded with url: /cluster (Caused by NewConnectionError('<urllib3.connection.HTTPConnection object at 0x7f82824e4130>: Failed to establish a new connection: [Errno 111] Connection refused'))
unit-pgbouncer-2: 02:03:18 ERROR juju.worker.meterstatus error running "meter-status-changed": charm missing from disk
unit-pgbouncer-3: 02:03:19 ERROR juju.worker.meterstatus error running "meter-status-changed": charm missing from disk
unit-another-pgbouncer-1: 02:03:20 ERROR juju.worker.meterstatus error running "meter-status-changed": charm missing from disk
unit-another-pgbouncer-0: 02:03:21 ERROR juju.worker.meterstatus error running "meter-status-changed": exit status 1
unit-pgbouncer-4: 02:05:20 ERROR juju.worker.meterstatus error running "meter-status-changed": charm missing from disk
unit-pgbouncer-5: 02:05:21 ERROR juju.worker.meterstatus error running "meter-status-changed": charm missing from disk
unit-another-pgbouncer-2: 02:05:22 ERROR juju.worker.meterstatus error running "meter-status-changed": charm missing from disk
unit-another-pgbouncer-3: 02:05:23 ERROR juju.worker.meterstatus error running "meter-status-changed": exit status 1
machine-7: 02:09:35 ERROR juju.worker.dependency "lxd-container-provisioner" manifold worker returned unexpected error: container types not yet available
machine-7: 02:09:35 ERROR juju.worker.dependency "kvm-container-provisioner" manifold worker returned unexpected error: container types not yet available
unit-postgresql-test-app-2: 02:09:35 ERROR juju.worker.meterstatus error running "meter-status-changed": charm missing from disk
unit-another-pgbouncer-9: 02:09:38 ERROR juju.worker.meterstatus error running "meter-status-changed": exit status 1
unit-pgbouncer-9: 02:09:38 ERROR juju.worker.meterstatus error running "meter-status-changed": exit status 1

[32mINFO    [0m pytest_operator.plugin:plugin.py:1024 Forgetting model main...