[32mINFO    [0m juju.model:model.py:2972 Waiting for model:
  pgbouncer/0 [idle] active: 
  pgbouncer/1 [idle] active:
[32mINFO    [0m pytest_operator.plugin:plugin.py:903 Model status:

Model  Controller           Cloud/Region         Version  SLA          Timestamp
test   localhost-localhost  localhost/localhost  3.4.6    unsupported  01:49:26Z

App                       Version  Status  Scale  Charm                     Channel        Rev  Exposed  Message
data-integrator                    active      2  data-integrator           latest/edge     80  no       
pgbouncer                 1.21.0   active      2  pgbouncer                                  0  no       
postgresql                14.13    active      2  postgresql                14/edge        530  no       
self-signed-certificates           active      1  self-signed-certificates  latest/stable  155  no       

Unit                         Workload  Agent  Machine  Public address  Ports     Message
data-integrator/0            active    idle   0        10.142.219.115            
  pgbouncer/1                active    idle            10.142.219.115  6432/tcp  
data-integrator/1*           active    idle   1        10.142.219.242            
  pgbouncer/0*               active    idle            10.142.219.242  6432/tcp  
postgresql/0*                active    idle   3        10.142.219.105  5432/tcp  Primary
postgresql/1                 active    idle   4        10.142.219.126  5432/tcp  
self-signed-certificates/0*  active    idle   2        10.142.219.95             

Machine  State    Address         Inst id        Base          AZ  Message
0        started  10.142.219.115  juju-917018-0  ubuntu@22.04      Running
1        started  10.142.219.242  juju-917018-1  ubuntu@22.04      Running
2        started  10.142.219.95   juju-917018-2  ubuntu@22.04      Running
3        started  10.142.219.105  juju-917018-3  ubuntu@22.04      Running
4        started  10.142.219.126  juju-917018-4  ubuntu@22.04      Running

[32mINFO    [0m pytest_operator.plugin:plugin.py:909 Juju error logs:

machine-1: 01:43:05 ERROR juju.worker.dependency "kvm-container-provisioner" manifold worker returned unexpected error: container types not yet available
machine-1: 01:43:05 ERROR juju.worker.dependency "lxd-container-provisioner" manifold worker returned unexpected error: container types not yet available
unit-data-integrator-1: 01:43:06 ERROR juju.worker.meterstatus error running "meter-status-changed": charm missing from disk
machine-3: 01:43:11 ERROR juju.worker.dependency "kvm-container-provisioner" manifold worker returned unexpected error: container types not yet available
machine-3: 01:43:11 ERROR juju.worker.dependency "lxd-container-provisioner" manifold worker returned unexpected error: container types not yet available
unit-postgresql-0: 01:43:12 ERROR juju.worker.meterstatus error running "meter-status-changed": charm missing from disk
unit-pgbouncer-0: 01:43:14 ERROR juju.worker.meterstatus error running "meter-status-changed": charm missing from disk
machine-2: 01:43:16 ERROR juju.worker.dependency "lxd-container-provisioner" manifold worker returned unexpected error: container types not yet available
machine-2: 01:43:16 ERROR juju.worker.dependency "kvm-container-provisioner" manifold worker returned unexpected error: container types not yet available
machine-4: 01:43:16 ERROR juju.worker.dependency "kvm-container-provisioner" manifold worker returned unexpected error: container types not yet available
machine-4: 01:43:16 ERROR juju.worker.dependency "lxd-container-provisioner" manifold worker returned unexpected error: container types not yet available
unit-self-signed-certificates-0: 01:43:16 ERROR juju.worker.meterstatus error running "meter-status-changed": charm missing from disk
unit-postgresql-1: 01:43:17 ERROR juju.worker.meterstatus error running "meter-status-changed": charm missing from disk
machine-0: 01:43:19 ERROR juju.worker.dependency "lxd-container-provisioner" manifold worker returned unexpected error: container types not yet available
machine-0: 01:43:19 ERROR juju.worker.dependency "kvm-container-provisioner" manifold worker returned unexpected error: container types not yet available
unit-data-integrator-0: 01:43:20 ERROR juju.worker.meterstatus error running "meter-status-changed": charm missing from disk
unit-pgbouncer-1: 01:43:27 ERROR juju.worker.meterstatus error running "meter-status-changed": charm missing from disk
unit-postgresql-0: 01:44:40 ERROR unit.postgresql/0.juju-log Unable to get the state of the cluster
Traceback (most recent call last):
  File "/var/lib/juju/agents/unit-postgresql-0/charm/venv/urllib3/connection.py", line 199, in _new_conn
    sock = connection.create_connection(
  File "/var/lib/juju/agents/unit-postgresql-0/charm/venv/urllib3/util/connection.py", line 85, in create_connection
    raise err
  File "/var/lib/juju/agents/unit-postgresql-0/charm/venv/urllib3/util/connection.py", line 73, in create_connection
    sock.connect(sa)
ConnectionRefusedError: [Errno 111] Connection refused

The above exception was the direct cause of the following exception:

Traceback (most recent call last):
  File "/var/lib/juju/agents/unit-postgresql-0/charm/venv/urllib3/connectionpool.py", line 789, in urlopen
    response = self._make_request(
  File "/var/lib/juju/agents/unit-postgresql-0/charm/venv/urllib3/connectionpool.py", line 495, in _make_request
    conn.request(
  File "/var/lib/juju/agents/unit-postgresql-0/charm/venv/urllib3/connection.py", line 441, in request
    self.endheaders()
  File "/usr/lib/python3.10/http/client.py", line 1278, in endheaders
    self._send_output(message_body, encode_chunked=encode_chunked)
  File "/usr/lib/python3.10/http/client.py", line 1038, in _send_output
    self.send(msg)
  File "/usr/lib/python3.10/http/client.py", line 976, in send
    self.connect()
  File "/var/lib/juju/agents/unit-postgresql-0/charm/venv/urllib3/connection.py", line 279, in connect
    self.sock = self._new_conn()
  File "/var/lib/juju/agents/unit-postgresql-0/charm/venv/urllib3/connection.py", line 214, in _new_conn
    raise NewConnectionError(
urllib3.exceptions.NewConnectionError: <urllib3.connection.HTTPConnection object at 0x7fe0b85e4e80>: Failed to establish a new connection: [Errno 111] Connection refused

The above exception was the direct cause of the following exception:

Traceback (most recent call last):
  File "/var/lib/juju/agents/unit-postgresql-0/charm/venv/requests/adapters.py", line 667, in send
    resp = conn.urlopen(
  File "/var/lib/juju/agents/unit-postgresql-0/charm/venv/urllib3/connectionpool.py", line 843, in urlopen
    retries = retries.increment(
  File "/var/lib/juju/agents/unit-postgresql-0/charm/venv/urllib3/util/retry.py", line 519, in increment
    raise MaxRetryError(_pool, url, reason) from reason  # type: ignore[arg-type]
urllib3.exceptions.MaxRetryError: HTTPConnectionPool(host='10.142.219.105', port=8008): Max retries exceeded with url: /cluster (Caused by NewConnectionError('<urllib3.connection.HTTPConnection object at 0x7fe0b85e4e80>: Failed to establish a new connection: [Errno 111] Connection refused'))

During handling of the above exception, another exception occurred:

Traceback (most recent call last):
  File "/var/lib/juju/agents/unit-postgresql-0/charm/src/cluster.py", line 531, in are_replicas_up
    response = requests.get(
  File "/var/lib/juju/agents/unit-postgresql-0/charm/venv/requests/api.py", line 73, in get
    return request("get", url, params=params, **kwargs)
  File "/var/lib/juju/agents/unit-postgresql-0/charm/venv/requests/api.py", line 59, in request
    return session.request(method=method, url=url, **kwargs)
  File "/var/lib/juju/agents/unit-postgresql-0/charm/venv/requests/sessions.py", line 589, in request
    resp = self.send(prep, **send_kwargs)
  File "/var/lib/juju/agents/unit-postgresql-0/charm/venv/requests/sessions.py", line 703, in send
    r = adapter.send(request, **kwargs)
  File "/var/lib/juju/agents/unit-postgresql-0/charm/venv/requests/adapters.py", line 700, in send
    raise ConnectionError(e, request=request)
requests.exceptions.ConnectionError: HTTPConnectionPool(host='10.142.219.105', port=8008): Max retries exceeded with url: /cluster (Caused by NewConnectionError('<urllib3.connection.HTTPConnection object at 0x7fe0b85e4e80>: Failed to establish a new connection: [Errno 111] Connection refused'))
unit-pgbouncer-0: 01:48:38 ERROR juju.worker.dependency "uniter" manifold worker returned unexpected error: relation scope id "8f4aab97-b4b6-4616-83e7-34ff82917018:r#8#self-signed-certificates": settings 8f4aab97-b4b6-4616-83e7-34ff82917018:r#8#self-signed-certificates not found (not found)
unit-pgbouncer-1: 01:48:40 ERROR juju.worker.dependency "uniter" manifold worker returned unexpected error: relation scope id "8f4aab97-b4b6-4616-83e7-34ff82917018:r#8#self-signed-certificates": settings 8f4aab97-b4b6-4616-83e7-34ff82917018:r#8#self-signed-certificates not found (not found)

[32mINFO    [0m pytest_operator.plugin:plugin.py:991 Forgetting model main...