[32mINFO    [0m pytest_operator.plugin:plugin.py:951 Model status:

Model    Controller     Cloud/Region         Version  SLA          Timestamp
testing  concierge-lxd  localhost/localhost  3.6.8    unsupported  02:04:35Z

App                       Version  Status   Scale  Charm                     Channel        Rev  Exposed  Message
data-integrator                    blocked      3  data-integrator           latest/edge    216  no       Please relate the data-integrator with the desired product
hacluster                 2.1.2    active       3  hacluster                 2.4/stable     131  no       Unit is ready and clustered
pgbouncer                          unknown      0  pgbouncer                                  0  no       
postgresql                14.18    active       2  postgresql                14/edge        871  no       
self-signed-certificates           active       1  self-signed-certificates  latest/stable  264  no       

Unit                         Workload     Agent      Machine  Public address  Ports     Message
data-integrator/0*           blocked      idle       0        10.197.132.144            Please relate the data-integrator with the desired product
  hacluster/0*               active       idle                10.197.132.144            Unit is ready and clustered
data-integrator/1            blocked      idle       1        10.197.132.41             Please relate the data-integrator with the desired product
  hacluster/1                active       idle                10.197.132.41             Unit is ready and clustered
data-integrator/2            blocked      idle       2        10.197.132.187            Please relate the data-integrator with the desired product
  hacluster/2                active       idle                10.197.132.187            Unit is ready and clustered
postgresql/0                 error        idle       4        10.197.132.158            hook failed: "database-peers-relation-changed"
postgresql/1*                maintenance  executing  5        10.197.132.19   5432/tcp  reconfiguring cluster
self-signed-certificates/0*  active       idle       3        10.197.132.44             

Machine  State    Address         Inst id        Base          AZ  Message
0        started  10.197.132.144  juju-8b6b66-0  ubuntu@22.04      Running
1        started  10.197.132.41   juju-8b6b66-1  ubuntu@22.04      Running
2        started  10.197.132.187  juju-8b6b66-2  ubuntu@22.04      Running
3        started  10.197.132.44   juju-8b6b66-3  ubuntu@22.04      Running
4        started  10.197.132.158  juju-8b6b66-4  ubuntu@22.04      Running
5        started  10.197.132.19   juju-8b6b66-5  ubuntu@22.04      Running

[32mINFO    [0m pytest_operator.plugin:plugin.py:957 Juju error logs:

machine-0: 01:57:50 ERROR juju.worker.dependency "kvm-container-provisioner" manifold worker returned unexpected error: container types not yet available
machine-0: 01:57:50 ERROR juju.worker.dependency "lxd-container-provisioner" manifold worker returned unexpected error: container types not yet available
unit-data-integrator-0: 01:57:51 ERROR juju.worker.meterstatus error running "meter-status-changed": charm missing from disk
machine-1: 02:00:36 ERROR juju.worker.dependency "lxd-container-provisioner" manifold worker returned unexpected error: container types not yet available
machine-1: 02:00:36 ERROR juju.worker.dependency "kvm-container-provisioner" manifold worker returned unexpected error: container types not yet available
unit-data-integrator-1: 02:00:37 ERROR juju.worker.meterstatus error running "meter-status-changed": charm missing from disk
machine-3: 02:01:09 ERROR juju.worker.dependency "kvm-container-provisioner" manifold worker returned unexpected error: container types not yet available
machine-3: 02:01:09 ERROR juju.worker.dependency "lxd-container-provisioner" manifold worker returned unexpected error: container types not yet available
unit-self-signed-certificates-0: 02:01:09 ERROR juju.worker.meterstatus error running "meter-status-changed": charm missing from disk
machine-5: 02:01:31 ERROR juju.worker.dependency "kvm-container-provisioner" manifold worker returned unexpected error: container types not yet available
machine-5: 02:01:31 ERROR juju.worker.dependency "lxd-container-provisioner" manifold worker returned unexpected error: container types not yet available
unit-postgresql-1: 02:01:31 ERROR juju.worker.meterstatus error running "meter-status-changed": charm missing from disk
machine-2: 02:01:52 ERROR juju.worker.dependency "lxd-container-provisioner" manifold worker returned unexpected error: container types not yet available
machine-2: 02:01:52 ERROR juju.worker.dependency "kvm-container-provisioner" manifold worker returned unexpected error: container types not yet available
unit-data-integrator-2: 02:01:52 ERROR juju.worker.meterstatus error running "meter-status-changed": charm missing from disk
machine-4: 02:02:06 ERROR juju.worker.dependency "kvm-container-provisioner" manifold worker returned unexpected error: container types not yet available
machine-4: 02:02:06 ERROR juju.worker.dependency "lxd-container-provisioner" manifold worker returned unexpected error: container types not yet available
unit-postgresql-0: 02:02:06 ERROR juju.worker.meterstatus error running "meter-status-changed": charm missing from disk
unit-postgresql-1: 02:02:26 ERROR unit.postgresql/1.juju-log Unable to get the state of the cluster
Traceback (most recent call last):
  File "/var/lib/juju/agents/unit-postgresql-1/charm/venv/lib/python3.10/site-packages/urllib3/connection.py", line 198, in _new_conn
    sock = connection.create_connection(
  File "/var/lib/juju/agents/unit-postgresql-1/charm/venv/lib/python3.10/site-packages/urllib3/util/connection.py", line 85, in create_connection
    raise err
  File "/var/lib/juju/agents/unit-postgresql-1/charm/venv/lib/python3.10/site-packages/urllib3/util/connection.py", line 73, in create_connection
    sock.connect(sa)
ConnectionRefusedError: [Errno 111] Connection refused

The above exception was the direct cause of the following exception:

Traceback (most recent call last):
  File "/var/lib/juju/agents/unit-postgresql-1/charm/venv/lib/python3.10/site-packages/urllib3/connectionpool.py", line 787, in urlopen
    response = self._make_request(
  File "/var/lib/juju/agents/unit-postgresql-1/charm/venv/lib/python3.10/site-packages/urllib3/connectionpool.py", line 493, in _make_request
    conn.request(
  File "/var/lib/juju/agents/unit-postgresql-1/charm/venv/lib/python3.10/site-packages/urllib3/connection.py", line 494, in request
    self.endheaders()
  File "/usr/lib/python3.10/http/client.py", line 1278, in endheaders
    self._send_output(message_body, encode_chunked=encode_chunked)
  File "/usr/lib/python3.10/http/client.py", line 1038, in _send_output
    self.send(msg)
  File "/usr/lib/python3.10/http/client.py", line 976, in send
    self.connect()
  File "/var/lib/juju/agents/unit-postgresql-1/charm/venv/lib/python3.10/site-packages/urllib3/connection.py", line 325, in connect
    self.sock = self._new_conn()
  File "/var/lib/juju/agents/unit-postgresql-1/charm/venv/lib/python3.10/site-packages/urllib3/connection.py", line 213, in _new_conn
    raise NewConnectionError(
urllib3.exceptions.NewConnectionError: <urllib3.connection.HTTPConnection object at 0x7f705344a920>: Failed to establish a new connection: [Errno 111] Connection refused

The above exception was the direct cause of the following exception:

Traceback (most recent call last):
  File "/var/lib/juju/agents/unit-postgresql-1/charm/venv/lib/python3.10/site-packages/requests/adapters.py", line 667, in send
    resp = conn.urlopen(
  File "/var/lib/juju/agents/unit-postgresql-1/charm/venv/lib/python3.10/site-packages/urllib3/connectionpool.py", line 841, in urlopen
    retries = retries.increment(
  File "/var/lib/juju/agents/unit-postgresql-1/charm/venv/lib/python3.10/site-packages/urllib3/util/retry.py", line 519, in increment
    raise MaxRetryError(_pool, url, reason) from reason  # type: ignore[arg-type]
urllib3.exceptions.MaxRetryError: HTTPConnectionPool(host='10.197.132.19', port=8008): Max retries exceeded with url: /cluster (Caused by NewConnectionError('<urllib3.connection.HTTPConnection object at 0x7f705344a920>: Failed to establish a new connection: [Errno 111] Connection refused'))

During handling of the above exception, another exception occurred:

Traceback (most recent call last):
  File "/var/lib/juju/agents/unit-postgresql-1/charm/src/cluster.py", line 571, in are_replicas_up
    response = requests.get(
  File "/var/lib/juju/agents/unit-postgresql-1/charm/venv/lib/python3.10/site-packages/requests/api.py", line 73, in get
    return request("get", url, params=params, **kwargs)
  File "/var/lib/juju/agents/unit-postgresql-1/charm/venv/lib/python3.10/site-packages/requests/api.py", line 59, in request
    return session.request(method=method, url=url, **kwargs)
  File "/var/lib/juju/agents/unit-postgresql-1/charm/venv/lib/python3.10/site-packages/requests/sessions.py", line 589, in request
    resp = self.send(prep, **send_kwargs)
  File "/var/lib/juju/agents/unit-postgresql-1/charm/venv/lib/python3.10/site-packages/requests/sessions.py", line 703, in send
    r = adapter.send(request, **kwargs)
  File "/var/lib/juju/agents/unit-postgresql-1/charm/venv/lib/python3.10/site-packages/requests/adapters.py", line 700, in send
    raise ConnectionError(e, request=request)
requests.exceptions.ConnectionError: HTTPConnectionPool(host='10.197.132.19', port=8008): Max retries exceeded with url: /cluster (Caused by NewConnectionError('<urllib3.connection.HTTPConnection object at 0x7f705344a920>: Failed to establish a new connection: [Errno 111] Connection refused'))
unit-postgresql-1: 02:02:38 ERROR unit.postgresql/1.juju-log Failed to list PostgreSQL database users: could not translate host name "None" to address: Temporary failure in name resolution

unit-postgresql-0: 02:04:01 ERROR unit.postgresql/0.juju-log An exception occurred when installing charmed-postgresql. Reason: Snap: 'charmed-postgresql' -- command ['snap', 'install', 'charmed-postgresql', '--revision="184"'] failed!
Stderr:
error: cannot perform the following tasks:
- Download snap "charmed-postgresql" (184) from channel "stable" (Get "https://canonical-bos01.cdn.snapcraftcontent.com/download-origin/canonical-lgw01/mAiAP9VqaDs9TXjjb9RpIULHkYwb9IoH_184.snap?interactive=1&token=1755410400_74c0c46d1b59cb1f51dc378b625f1a1cbbf6fd62": net/http: timeout awaiting response headers)

Latest logs:
Aug 17 02:01:36 juju-8b6b66-4 systemd[1]: /lib/systemd/system/snapd.service:23: Unknown key name 'RestartMode' in section 'Service', ignoring.
Aug 17 02:01:40 juju-8b6b66-4 systemd[1]: /lib/systemd/system/snapd.service:23: Unknown key name 'RestartMode' in section 'Service', ignoring.
Aug 17 02:01:40 juju-8b6b66-4 systemd[1]: /lib/systemd/system/snapd.service:23: Unknown key name 'RestartMode' in section 'Service', ignoring.
Aug 17 02:01:51 juju-8b6b66-4 snapd[1980]: storehelpers.go:916: cannot refresh: snap has no updates available: "core20", "lxd", "snapd"
Aug 17 02:01:56 juju-8b6b66-4 systemd[1]: /lib/systemd/system/snapd.service:23: Unknown key name 'RestartMode' in section 'Service', ignoring.
Aug 17 02:01:56 juju-8b6b66-4 systemd[1]: /lib/systemd/system/snapd.service:23: Unknown key name 'RestartMode' in section 'Service', ignoring.
Aug 17 02:02:05 juju-8b6b66-4 systemd[1]: /lib/systemd/system/snapd.service:23: Unknown key name 'RestartMode' in section 'Service', ignoring.
Aug 17 02:02:05 juju-8b6b66-4 systemd[1]: /lib/systemd/system/snapd.service:23: Unknown key name 'RestartMode' in section 'Service', ignoring.
Aug 17 02:02:05 juju-8b6b66-4 systemd[1]: /lib/systemd/system/snapd.service:23: Unknown key name 'RestartMode' in section 'Service', ignoring.
Aug 17 02:02:19 juju-8b6b66-4 snapd[1980]: api_snaps.go:467: Installing snap "charmed-postgresql" revision 184
Aug 17 02:02:19 juju-8b6b66-4 groupadd[3269]: group added to /etc/group: name=snapd-range-524288-root, GID=524288
Aug 17 02:02:19 juju-8b6b66-4 groupadd[3269]: group added to /etc/gshadow: name=snapd-range-524288-root
Aug 17 02:02:19 juju-8b6b66-4 groupadd[3269]: new group: name=snapd-range-524288-root, GID=524288
Aug 17 02:02:19 juju-8b6b66-4 useradd[3275]: new user: name=snapd-range-524288-root, UID=524288, GID=524288, home=/nonexistent, shell=/usr/bin/false, from=none
Aug 17 02:02:19 juju-8b6b66-4 groupadd[3284]: group added to /etc/group: name=snap_daemon, GID=584788
Aug 17 02:02:19 juju-8b6b66-4 groupadd[3284]: group added to /etc/gshadow: name=snap_daemon
Aug 17 02:02:19 juju-8b6b66-4 groupadd[3284]: new group: name=snap_daemon, GID=584788
Aug 17 02:02:19 juju-8b6b66-4 useradd[3290]: new user: name=snap_daemon, UID=584788, GID=584788, home=/nonexistent, shell=/usr/bin/false, from=none
Aug 17 02:02:23 juju-8b6b66-4 systemd[1]: /lib/systemd/system/snapd.service:23: Unknown key name 'RestartMode' in section 'Service', ignoring.
Aug 17 02:04:01 juju-8b6b66-4 snapd[1980]: taskrunner.go:299: Change 5 task (Download snap "charmed-postgresql" (184) from channel "stable") failed: Get "https://canonical-bos01.cdn.snapcraftcontent.com/download-origin/canonical-lgw01/mAiAP9VqaDs9TXjjb9RpIULHkYwb9IoH_184.snap?interactive=1&token=1755410400_74c0c46d1b59cb1f51dc378b625f1a1cbbf6fd62": net/http: timeout awaiting response headers


[32mINFO    [0m pytest_operator.plugin:plugin.py:1039 Forgetting model main...