[32mINFO    [0m pytest_operator.plugin:plugin.py:937 Model status:

Model    Controller     Cloud/Region         Version  SLA          Timestamp
testing  concierge-lxd  localhost/localhost  3.6.6    unsupported  02:17:43Z

App                  Version  Status  Scale  Charm                Channel      Rev  Exposed  Message
another-application           active      1  postgresql-test-app  latest/edge  383  no       
another-pgbouncer    1.21.0   active      1  pgbouncer                           1  no       
another-postgresql   14.17    active      2  postgresql           14/edge      764  no       
pgbouncer            1.21.0   active      1  pgbouncer                           0  no       
postgresql           14.17    active      2  postgresql           14/edge      764  no       
postgresql-test-app           active      1  postgresql-test-app  latest/edge  383  no       received database credentials of the first database

Unit                    Workload  Agent  Machine  Public address  Ports     Message
another-application/0*  active    idle   4        10.7.81.62                
another-postgresql/0*   active    idle   5        10.7.81.55      5432/tcp  Primary
another-postgresql/1    active    idle   6        10.7.81.79      5432/tcp  
postgresql-test-app/1*  active    idle   3        10.7.81.135               received database credentials of the first database
  another-pgbouncer/2*  active    idle            10.7.81.135               
  pgbouncer/4*          active    idle            10.7.81.135               
postgresql/0            active    idle   1        10.7.81.70      5432/tcp  
postgresql/1*           active    idle   2        10.7.81.157     5432/tcp  Primary

Machine  State    Address      Inst id        Base          AZ  Message
1        started  10.7.81.70   juju-672561-1  ubuntu@22.04      Running
2        started  10.7.81.157  juju-672561-2  ubuntu@22.04      Running
3        started  10.7.81.135  juju-672561-3  ubuntu@22.04      Running
4        started  10.7.81.62   juju-672561-4  ubuntu@22.04      Running
5        started  10.7.81.55   juju-672561-5  ubuntu@22.04      Running
6        started  10.7.81.79   juju-672561-6  ubuntu@22.04      Running

[32mINFO    [0m pytest_operator.plugin:plugin.py:943 Juju error logs:

machine-0: 01:43:52 ERROR juju.worker.dependency "kvm-container-provisioner" manifold worker returned unexpected error: container types not yet available
machine-0: 01:43:52 ERROR juju.worker.dependency "lxd-container-provisioner" manifold worker returned unexpected error: container types not yet available
unit-postgresql-test-app-0: 01:43:52 ERROR juju.worker.meterstatus error running "meter-status-changed": charm missing from disk
machine-2: 01:45:09 ERROR juju.worker.dependency "lxd-container-provisioner" manifold worker returned unexpected error: container types not yet available
machine-2: 01:45:09 ERROR juju.worker.dependency "kvm-container-provisioner" manifold worker returned unexpected error: container types not yet available
unit-postgresql-1: 01:45:09 ERROR juju.worker.meterstatus error running "meter-status-changed": charm missing from disk
machine-1: 01:45:12 ERROR juju.worker.dependency "lxd-container-provisioner" manifold worker returned unexpected error: container types not yet available
machine-1: 01:45:12 ERROR juju.worker.dependency "kvm-container-provisioner" manifold worker returned unexpected error: container types not yet available
unit-postgresql-0: 01:45:12 ERROR juju.worker.meterstatus error running "meter-status-changed": charm missing from disk
unit-postgresql-1: 01:45:44 ERROR unit.postgresql/1.juju-log Unable to get the state of the cluster
Traceback (most recent call last):
  File "/var/lib/juju/agents/unit-postgresql-1/charm/venv/lib/python3.10/site-packages/urllib3/connection.py", line 198, in _new_conn
    sock = connection.create_connection(
  File "/var/lib/juju/agents/unit-postgresql-1/charm/venv/lib/python3.10/site-packages/urllib3/util/connection.py", line 85, in create_connection
    raise err
  File "/var/lib/juju/agents/unit-postgresql-1/charm/venv/lib/python3.10/site-packages/urllib3/util/connection.py", line 73, in create_connection
    sock.connect(sa)
ConnectionRefusedError: [Errno 111] Connection refused

The above exception was the direct cause of the following exception:

Traceback (most recent call last):
  File "/var/lib/juju/agents/unit-postgresql-1/charm/venv/lib/python3.10/site-packages/urllib3/connectionpool.py", line 787, in urlopen
    response = self._make_request(
  File "/var/lib/juju/agents/unit-postgresql-1/charm/venv/lib/python3.10/site-packages/urllib3/connectionpool.py", line 493, in _make_request
    conn.request(
  File "/var/lib/juju/agents/unit-postgresql-1/charm/venv/lib/python3.10/site-packages/urllib3/connection.py", line 445, in request
    self.endheaders()
  File "/usr/lib/python3.10/http/client.py", line 1278, in endheaders
    self._send_output(message_body, encode_chunked=encode_chunked)
  File "/usr/lib/python3.10/http/client.py", line 1038, in _send_output
    self.send(msg)
  File "/usr/lib/python3.10/http/client.py", line 976, in send
    self.connect()
  File "/var/lib/juju/agents/unit-postgresql-1/charm/venv/lib/python3.10/site-packages/urllib3/connection.py", line 276, in connect
    self.sock = self._new_conn()
  File "/var/lib/juju/agents/unit-postgresql-1/charm/venv/lib/python3.10/site-packages/urllib3/connection.py", line 213, in _new_conn
    raise NewConnectionError(
urllib3.exceptions.NewConnectionError: <urllib3.connection.HTTPConnection object at 0x7f34b491f9a0>: Failed to establish a new connection: [Errno 111] Connection refused

The above exception was the direct cause of the following exception:

Traceback (most recent call last):
  File "/var/lib/juju/agents/unit-postgresql-1/charm/venv/lib/python3.10/site-packages/requests/adapters.py", line 667, in send
    resp = conn.urlopen(
  File "/var/lib/juju/agents/unit-postgresql-1/charm/venv/lib/python3.10/site-packages/urllib3/connectionpool.py", line 841, in urlopen
    retries = retries.increment(
  File "/var/lib/juju/agents/unit-postgresql-1/charm/venv/lib/python3.10/site-packages/urllib3/util/retry.py", line 519, in increment
    raise MaxRetryError(_pool, url, reason) from reason  # type: ignore[arg-type]
urllib3.exceptions.MaxRetryError: HTTPConnectionPool(host='10.7.81.157', port=8008): Max retries exceeded with url: /cluster (Caused by NewConnectionError('<urllib3.connection.HTTPConnection object at 0x7f34b491f9a0>: Failed to establish a new connection: [Errno 111] Connection refused'))

During handling of the above exception, another exception occurred:

Traceback (most recent call last):
  File "/var/lib/juju/agents/unit-postgresql-1/charm/src/cluster.py", line 568, in are_replicas_up
    response = requests.get(
  File "/var/lib/juju/agents/unit-postgresql-1/charm/venv/lib/python3.10/site-packages/requests/api.py", line 73, in get
    return request("get", url, params=params, **kwargs)
  File "/var/lib/juju/agents/unit-postgresql-1/charm/venv/lib/python3.10/site-packages/requests/api.py", line 59, in request
    return session.request(method=method, url=url, **kwargs)
  File "/var/lib/juju/agents/unit-postgresql-1/charm/venv/lib/python3.10/site-packages/requests/sessions.py", line 589, in request
    resp = self.send(prep, **send_kwargs)
  File "/var/lib/juju/agents/unit-postgresql-1/charm/venv/lib/python3.10/site-packages/requests/sessions.py", line 703, in send
    r = adapter.send(request, **kwargs)
  File "/var/lib/juju/agents/unit-postgresql-1/charm/venv/lib/python3.10/site-packages/requests/adapters.py", line 700, in send
    raise ConnectionError(e, request=request)
requests.exceptions.ConnectionError: HTTPConnectionPool(host='10.7.81.157', port=8008): Max retries exceeded with url: /cluster (Caused by NewConnectionError('<urllib3.connection.HTTPConnection object at 0x7f34b491f9a0>: Failed to establish a new connection: [Errno 111] Connection refused'))
unit-pgbouncer-0: 01:48:07 ERROR juju.worker.meterstatus error running "meter-status-changed": charm missing from disk
unit-postgresql-test-app-0: 01:56:13 ERROR unit.postgresql-test-app/0.juju-log Uncaught exception while in charm code:
Traceback (most recent call last):
  File "/var/lib/juju/agents/unit-postgresql-test-app-0/charm/src/charm.py", line 560, in <module>
    main(ApplicationCharm)
  File "/var/lib/juju/agents/unit-postgresql-test-app-0/charm/venv/lib/python3.10/site-packages/ops/__init__.py", line 356, in __call__
    return _main.main(charm_class=charm_class, use_juju_for_storage=use_juju_for_storage)
  File "/var/lib/juju/agents/unit-postgresql-test-app-0/charm/venv/lib/python3.10/site-packages/ops/_main.py", line 474, in main
    manager.run()
  File "/var/lib/juju/agents/unit-postgresql-test-app-0/charm/venv/lib/python3.10/site-packages/ops/_main.py", line 458, in run
    self._emit()
  File "/var/lib/juju/agents/unit-postgresql-test-app-0/charm/venv/lib/python3.10/site-packages/ops/_main.py", line 402, in _emit
    self._emit_charm_event(self.dispatcher.event_name)
  File "/var/lib/juju/agents/unit-postgresql-test-app-0/charm/venv/lib/python3.10/site-packages/ops/_main.py", line 437, in _emit_charm_event
    event_to_emit.emit(*args, **kwargs)
  File "/var/lib/juju/agents/unit-postgresql-test-app-0/charm/venv/lib/python3.10/site-packages/ops/framework.py", line 351, in emit
    framework._emit(event)
  File "/var/lib/juju/agents/unit-postgresql-test-app-0/charm/venv/lib/python3.10/site-packages/ops/framework.py", line 923, in _emit
    self._reemit(event_path)
  File "/var/lib/juju/agents/unit-postgresql-test-app-0/charm/venv/lib/python3.10/site-packages/ops/framework.py", line 1029, in _reemit
    custom_handler(event)
  File "/var/lib/juju/agents/unit-postgresql-test-app-0/charm/src/charm.py", line 485, in _on_run_sql_action
    connection = self.connect_to_database(
  File "/var/lib/juju/agents/unit-postgresql-test-app-0/charm/src/charm.py", line 554, in connect_to_database
    connection = psycopg2.connect(connstr)
  File "/var/lib/juju/agents/unit-postgresql-test-app-0/charm/venv/lib/python3.10/site-packages/psycopg2/__init__.py", line 122, in connect
    conn = _connect(dsn, connection_factory=connection_factory, **kwasync)
psycopg2.OperationalError: connection to server on socket "/var/snap/charmed-pgbouncer/current/run/pgbouncer/pgbouncer/instance_0/.s.PGSQL.6432" failed: timeout expired

unit-postgresql-test-app-0: 01:56:14 ERROR unit.postgresql-test-app/0.juju-log Uncaught exception while in charm code:
Traceback (most recent call last):
  File "/var/lib/juju/agents/unit-postgresql-test-app-0/charm/src/charm.py", line 560, in <module>
    main(ApplicationCharm)
  File "/var/lib/juju/agents/unit-postgresql-test-app-0/charm/venv/lib/python3.10/site-packages/ops/__init__.py", line 356, in __call__
    return _main.main(charm_class=charm_class, use_juju_for_storage=use_juju_for_storage)
  File "/var/lib/juju/agents/unit-postgresql-test-app-0/charm/venv/lib/python3.10/site-packages/ops/_main.py", line 474, in main
    manager.run()
  File "/var/lib/juju/agents/unit-postgresql-test-app-0/charm/venv/lib/python3.10/site-packages/ops/_main.py", line 458, in run
    self._emit()
  File "/var/lib/juju/agents/unit-postgresql-test-app-0/charm/venv/lib/python3.10/site-packages/ops/_main.py", line 402, in _emit
    self._emit_charm_event(self.dispatcher.event_name)
  File "/var/lib/juju/agents/unit-postgresql-test-app-0/charm/venv/lib/python3.10/site-packages/ops/_main.py", line 437, in _emit_charm_event
    event_to_emit.emit(*args, **kwargs)
  File "/var/lib/juju/agents/unit-postgresql-test-app-0/charm/venv/lib/python3.10/site-packages/ops/framework.py", line 351, in emit
    framework._emit(event)
  File "/var/lib/juju/agents/unit-postgresql-test-app-0/charm/venv/lib/python3.10/site-packages/ops/framework.py", line 923, in _emit
    self._reemit(event_path)
  File "/var/lib/juju/agents/unit-postgresql-test-app-0/charm/venv/lib/python3.10/site-packages/ops/framework.py", line 1029, in _reemit
    custom_handler(event)
  File "/var/lib/juju/agents/unit-postgresql-test-app-0/charm/src/charm.py", line 485, in _on_run_sql_action
    connection = self.connect_to_database(
  File "/var/lib/juju/agents/unit-postgresql-test-app-0/charm/src/charm.py", line 554, in connect_to_database
    connection = psycopg2.connect(connstr)
  File "/var/lib/juju/agents/unit-postgresql-test-app-0/charm/venv/lib/python3.10/site-packages/psycopg2/__init__.py", line 122, in connect
    conn = _connect(dsn, connection_factory=connection_factory, **kwasync)
psycopg2.OperationalError: connection to server on socket "/var/snap/charmed-pgbouncer/current/run/pgbouncer/pgbouncer/instance_0/.s.PGSQL.6432" failed: FATAL:  server login has been failing, try again later (server_login_retry)

unit-postgresql-test-app-0: 01:56:15 ERROR unit.postgresql-test-app/0.juju-log Uncaught exception while in charm code:
Traceback (most recent call last):
  File "/var/lib/juju/agents/unit-postgresql-test-app-0/charm/src/charm.py", line 560, in <module>
    main(ApplicationCharm)
  File "/var/lib/juju/agents/unit-postgresql-test-app-0/charm/venv/lib/python3.10/site-packages/ops/__init__.py", line 356, in __call__
    return _main.main(charm_class=charm_class, use_juju_for_storage=use_juju_for_storage)
  File "/var/lib/juju/agents/unit-postgresql-test-app-0/charm/venv/lib/python3.10/site-packages/ops/_main.py", line 474, in main
    manager.run()
  File "/var/lib/juju/agents/unit-postgresql-test-app-0/charm/venv/lib/python3.10/site-packages/ops/_main.py", line 458, in run
    self._emit()
  File "/var/lib/juju/agents/unit-postgresql-test-app-0/charm/venv/lib/python3.10/site-packages/ops/_main.py", line 402, in _emit
    self._emit_charm_event(self.dispatcher.event_name)
  File "/var/lib/juju/agents/unit-postgresql-test-app-0/charm/venv/lib/python3.10/site-packages/ops/_main.py", line 437, in _emit_charm_event
    event_to_emit.emit(*args, **kwargs)
  File "/var/lib/juju/agents/unit-postgresql-test-app-0/charm/venv/lib/python3.10/site-packages/ops/framework.py", line 351, in emit
    framework._emit(event)
  File "/var/lib/juju/agents/unit-postgresql-test-app-0/charm/venv/lib/python3.10/site-packages/ops/framework.py", line 923, in _emit
    self._reemit(event_path)
  File "/var/lib/juju/agents/unit-postgresql-test-app-0/charm/venv/lib/python3.10/site-packages/ops/framework.py", line 1029, in _reemit
    custom_handler(event)
  File "/var/lib/juju/agents/unit-postgresql-test-app-0/charm/src/charm.py", line 485, in _on_run_sql_action
    connection = self.connect_to_database(
  File "/var/lib/juju/agents/unit-postgresql-test-app-0/charm/src/charm.py", line 554, in connect_to_database
    connection = psycopg2.connect(connstr)
  File "/var/lib/juju/agents/unit-postgresql-test-app-0/charm/venv/lib/python3.10/site-packages/psycopg2/__init__.py", line 122, in connect
    conn = _connect(dsn, connection_factory=connection_factory, **kwasync)
psycopg2.OperationalError: connection to server on socket "/var/snap/charmed-pgbouncer/current/run/pgbouncer/pgbouncer/instance_0/.s.PGSQL.6432" failed: FATAL:  server login has been failing, try again later (server_login_retry)

unit-postgresql-test-app-0: 01:56:34 ERROR unit.postgresql-test-app/0.juju-log Uncaught exception while in charm code:
Traceback (most recent call last):
  File "/var/lib/juju/agents/unit-postgresql-test-app-0/charm/src/charm.py", line 560, in <module>
    main(ApplicationCharm)
  File "/var/lib/juju/agents/unit-postgresql-test-app-0/charm/venv/lib/python3.10/site-packages/ops/__init__.py", line 356, in __call__
    return _main.main(charm_class=charm_class, use_juju_for_storage=use_juju_for_storage)
  File "/var/lib/juju/agents/unit-postgresql-test-app-0/charm/venv/lib/python3.10/site-packages/ops/_main.py", line 474, in main
    manager.run()
  File "/var/lib/juju/agents/unit-postgresql-test-app-0/charm/venv/lib/python3.10/site-packages/ops/_main.py", line 458, in run
    self._emit()
  File "/var/lib/juju/agents/unit-postgresql-test-app-0/charm/venv/lib/python3.10/site-packages/ops/_main.py", line 402, in _emit
    self._emit_charm_event(self.dispatcher.event_name)
  File "/var/lib/juju/agents/unit-postgresql-test-app-0/charm/venv/lib/python3.10/site-packages/ops/_main.py", line 437, in _emit_charm_event
    event_to_emit.emit(*args, **kwargs)
  File "/var/lib/juju/agents/unit-postgresql-test-app-0/charm/venv/lib/python3.10/site-packages/ops/framework.py", line 351, in emit
    framework._emit(event)
  File "/var/lib/juju/agents/unit-postgresql-test-app-0/charm/venv/lib/python3.10/site-packages/ops/framework.py", line 923, in _emit
    self._reemit(event_path)
  File "/var/lib/juju/agents/unit-postgresql-test-app-0/charm/venv/lib/python3.10/site-packages/ops/framework.py", line 1029, in _reemit
    custom_handler(event)
  File "/var/lib/juju/agents/unit-postgresql-test-app-0/charm/src/charm.py", line 485, in _on_run_sql_action
    connection = self.connect_to_database(
  File "/var/lib/juju/agents/unit-postgresql-test-app-0/charm/src/charm.py", line 554, in connect_to_database
    connection = psycopg2.connect(connstr)
  File "/var/lib/juju/agents/unit-postgresql-test-app-0/charm/venv/lib/python3.10/site-packages/psycopg2/__init__.py", line 122, in connect
    conn = _connect(dsn, connection_factory=connection_factory, **kwasync)
psycopg2.OperationalError: connection to server on socket "/var/snap/charmed-pgbouncer/current/run/pgbouncer/pgbouncer/instance_0/.s.PGSQL.6432" failed: FATAL:  server login has been failing, try again later (server_login_retry)

unit-postgresql-test-app-0: 01:56:36 ERROR unit.postgresql-test-app/0.juju-log Uncaught exception while in charm code:
Traceback (most recent call last):
  File "/var/lib/juju/agents/unit-postgresql-test-app-0/charm/src/charm.py", line 560, in <module>
    main(ApplicationCharm)
  File "/var/lib/juju/agents/unit-postgresql-test-app-0/charm/venv/lib/python3.10/site-packages/ops/__init__.py", line 356, in __call__
    return _main.main(charm_class=charm_class, use_juju_for_storage=use_juju_for_storage)
  File "/var/lib/juju/agents/unit-postgresql-test-app-0/charm/venv/lib/python3.10/site-packages/ops/_main.py", line 474, in main
    manager.run()
  File "/var/lib/juju/agents/unit-postgresql-test-app-0/charm/venv/lib/python3.10/site-packages/ops/_main.py", line 458, in run
    self._emit()
  File "/var/lib/juju/agents/unit-postgresql-test-app-0/charm/venv/lib/python3.10/site-packages/ops/_main.py", line 402, in _emit
    self._emit_charm_event(self.dispatcher.event_name)
  File "/var/lib/juju/agents/unit-postgresql-test-app-0/charm/venv/lib/python3.10/site-packages/ops/_main.py", line 437, in _emit_charm_event
    event_to_emit.emit(*args, **kwargs)
  File "/var/lib/juju/agents/unit-postgresql-test-app-0/charm/venv/lib/python3.10/site-packages/ops/framework.py", line 351, in emit
    framework._emit(event)
  File "/var/lib/juju/agents/unit-postgresql-test-app-0/charm/venv/lib/python3.10/site-packages/ops/framework.py", line 923, in _emit
    self._reemit(event_path)
  File "/var/lib/juju/agents/unit-postgresql-test-app-0/charm/venv/lib/python3.10/site-packages/ops/framework.py", line 1029, in _reemit
    custom_handler(event)
  File "/var/lib/juju/agents/unit-postgresql-test-app-0/charm/src/charm.py", line 485, in _on_run_sql_action
    connection = self.connect_to_database(
  File "/var/lib/juju/agents/unit-postgresql-test-app-0/charm/src/charm.py", line 554, in connect_to_database
    connection = psycopg2.connect(connstr)
  File "/var/lib/juju/agents/unit-postgresql-test-app-0/charm/venv/lib/python3.10/site-packages/psycopg2/__init__.py", line 122, in connect
    conn = _connect(dsn, connection_factory=connection_factory, **kwasync)
psycopg2.OperationalError: connection to server on socket "/var/snap/charmed-pgbouncer/current/run/pgbouncer/pgbouncer/instance_0/.s.PGSQL.6432" failed: FATAL:  server login has been failing, try again later (server_login_retry)

unit-postgresql-test-app-0: 01:56:38 ERROR unit.postgresql-test-app/0.juju-log Uncaught exception while in charm code:
Traceback (most recent call last):
  File "/var/lib/juju/agents/unit-postgresql-test-app-0/charm/src/charm.py", line 560, in <module>
    main(ApplicationCharm)
  File "/var/lib/juju/agents/unit-postgresql-test-app-0/charm/venv/lib/python3.10/site-packages/ops/__init__.py", line 356, in __call__
    return _main.main(charm_class=charm_class, use_juju_for_storage=use_juju_for_storage)
  File "/var/lib/juju/agents/unit-postgresql-test-app-0/charm/venv/lib/python3.10/site-packages/ops/_main.py", line 474, in main
    manager.run()
  File "/var/lib/juju/agents/unit-postgresql-test-app-0/charm/venv/lib/python3.10/site-packages/ops/_main.py", line 458, in run
    self._emit()
  File "/var/lib/juju/agents/unit-postgresql-test-app-0/charm/venv/lib/python3.10/site-packages/ops/_main.py", line 402, in _emit
    self._emit_charm_event(self.dispatcher.event_name)
  File "/var/lib/juju/agents/unit-postgresql-test-app-0/charm/venv/lib/python3.10/site-packages/ops/_main.py", line 437, in _emit_charm_event
    event_to_emit.emit(*args, **kwargs)
  File "/var/lib/juju/agents/unit-postgresql-test-app-0/charm/venv/lib/python3.10/site-packages/ops/framework.py", line 351, in emit
    framework._emit(event)
  File "/var/lib/juju/agents/unit-postgresql-test-app-0/charm/venv/lib/python3.10/site-packages/ops/framework.py", line 923, in _emit
    self._reemit(event_path)
  File "/var/lib/juju/agents/unit-postgresql-test-app-0/charm/venv/lib/python3.10/site-packages/ops/framework.py", line 1029, in _reemit
    custom_handler(event)
  File "/var/lib/juju/agents/unit-postgresql-test-app-0/charm/src/charm.py", line 485, in _on_run_sql_action
    connection = self.connect_to_database(
  File "/var/lib/juju/agents/unit-postgresql-test-app-0/charm/src/charm.py", line 554, in connect_to_database
    connection = psycopg2.connect(connstr)
  File "/var/lib/juju/agents/unit-postgresql-test-app-0/charm/venv/lib/python3.10/site-packages/psycopg2/__init__.py", line 122, in connect
    conn = _connect(dsn, connection_factory=connection_factory, **kwasync)
psycopg2.OperationalError: connection to server on socket "/var/snap/charmed-pgbouncer/current/run/pgbouncer/pgbouncer/instance_0/.s.PGSQL.6432" failed: FATAL:  server login has been failing, try again later (server_login_retry)

unit-postgresql-test-app-0: 01:56:40 ERROR unit.postgresql-test-app/0.juju-log Uncaught exception while in charm code:
Traceback (most recent call last):
  File "/var/lib/juju/agents/unit-postgresql-test-app-0/charm/src/charm.py", line 560, in <module>
    main(ApplicationCharm)
  File "/var/lib/juju/agents/unit-postgresql-test-app-0/charm/venv/lib/python3.10/site-packages/ops/__init__.py", line 356, in __call__
    return _main.main(charm_class=charm_class, use_juju_for_storage=use_juju_for_storage)
  File "/var/lib/juju/agents/unit-postgresql-test-app-0/charm/venv/lib/python3.10/site-packages/ops/_main.py", line 474, in main
    manager.run()
  File "/var/lib/juju/agents/unit-postgresql-test-app-0/charm/venv/lib/python3.10/site-packages/ops/_main.py", line 458, in run
    self._emit()
  File "/var/lib/juju/agents/unit-postgresql-test-app-0/charm/venv/lib/python3.10/site-packages/ops/_main.py", line 402, in _emit
    self._emit_charm_event(self.dispatcher.event_name)
  File "/var/lib/juju/agents/unit-postgresql-test-app-0/charm/venv/lib/python3.10/site-packages/ops/_main.py", line 437, in _emit_charm_event
    event_to_emit.emit(*args, **kwargs)
  File "/var/lib/juju/agents/unit-postgresql-test-app-0/charm/venv/lib/python3.10/site-packages/ops/framework.py", line 351, in emit
    framework._emit(event)
  File "/var/lib/juju/agents/unit-postgresql-test-app-0/charm/venv/lib/python3.10/site-packages/ops/framework.py", line 923, in _emit
    self._reemit(event_path)
  File "/var/lib/juju/agents/unit-postgresql-test-app-0/charm/venv/lib/python3.10/site-packages/ops/framework.py", line 1029, in _reemit
    custom_handler(event)
  File "/var/lib/juju/agents/unit-postgresql-test-app-0/charm/src/charm.py", line 485, in _on_run_sql_action
    connection = self.connect_to_database(
  File "/var/lib/juju/agents/unit-postgresql-test-app-0/charm/src/charm.py", line 554, in connect_to_database
    connection = psycopg2.connect(connstr)
  File "/var/lib/juju/agents/unit-postgresql-test-app-0/charm/venv/lib/python3.10/site-packages/psycopg2/__init__.py", line 122, in connect
    conn = _connect(dsn, connection_factory=connection_factory, **kwasync)
psycopg2.OperationalError: connection to server on socket "/var/snap/charmed-pgbouncer/current/run/pgbouncer/pgbouncer/instance_0/.s.PGSQL.6432" failed: FATAL:  server login has been failing, try again later (server_login_retry)

unit-postgresql-test-app-0: 01:56:42 ERROR unit.postgresql-test-app/0.juju-log Uncaught exception while in charm code:
Traceback (most recent call last):
  File "/var/lib/juju/agents/unit-postgresql-test-app-0/charm/src/charm.py", line 560, in <module>
    main(ApplicationCharm)
  File "/var/lib/juju/agents/unit-postgresql-test-app-0/charm/venv/lib/python3.10/site-packages/ops/__init__.py", line 356, in __call__
    return _main.main(charm_class=charm_class, use_juju_for_storage=use_juju_for_storage)
  File "/var/lib/juju/agents/unit-postgresql-test-app-0/charm/venv/lib/python3.10/site-packages/ops/_main.py", line 474, in main
    manager.run()
  File "/var/lib/juju/agents/unit-postgresql-test-app-0/charm/venv/lib/python3.10/site-packages/ops/_main.py", line 458, in run
    self._emit()
  File "/var/lib/juju/agents/unit-postgresql-test-app-0/charm/venv/lib/python3.10/site-packages/ops/_main.py", line 402, in _emit
    self._emit_charm_event(self.dispatcher.event_name)
  File "/var/lib/juju/agents/unit-postgresql-test-app-0/charm/venv/lib/python3.10/site-packages/ops/_main.py", line 437, in _emit_charm_event
    event_to_emit.emit(*args, **kwargs)
  File "/var/lib/juju/agents/unit-postgresql-test-app-0/charm/venv/lib/python3.10/site-packages/ops/framework.py", line 351, in emit
    framework._emit(event)
  File "/var/lib/juju/agents/unit-postgresql-test-app-0/charm/venv/lib/python3.10/site-packages/ops/framework.py", line 923, in _emit
    self._reemit(event_path)
  File "/var/lib/juju/agents/unit-postgresql-test-app-0/charm/venv/lib/python3.10/site-packages/ops/framework.py", line 1029, in _reemit
    custom_handler(event)
  File "/var/lib/juju/agents/unit-postgresql-test-app-0/charm/src/charm.py", line 485, in _on_run_sql_action
    connection = self.connect_to_database(
  File "/var/lib/juju/agents/unit-postgresql-test-app-0/charm/src/charm.py", line 554, in connect_to_database
    connection = psycopg2.connect(connstr)
  File "/var/lib/juju/agents/unit-postgresql-test-app-0/charm/venv/lib/python3.10/site-packages/psycopg2/__init__.py", line 122, in connect
    conn = _connect(dsn, connection_factory=connection_factory, **kwasync)
psycopg2.OperationalError: connection to server on socket "/var/snap/charmed-pgbouncer/current/run/pgbouncer/pgbouncer/instance_0/.s.PGSQL.6432" failed: FATAL:  server login has been failing, try again later (server_login_retry)

machine-3: 01:57:46 ERROR juju.worker.dependency "lxd-container-provisioner" manifold worker returned unexpected error: container types not yet available
machine-3: 01:57:46 ERROR juju.worker.dependency "kvm-container-provisioner" manifold worker returned unexpected error: container types not yet available
unit-postgresql-test-app-1: 01:57:46 ERROR juju.worker.meterstatus error running "meter-status-changed": charm missing from disk
unit-pgbouncer-1: 01:57:49 ERROR juju.worker.meterstatus error running "meter-status-changed": exit status 1
unit-postgresql-test-app-0: 01:58:49 ERROR unit.postgresql-test-app/0.juju-log Uncaught exception while in charm code:
Traceback (most recent call last):
  File "/var/lib/juju/agents/unit-postgresql-test-app-0/charm/src/charm.py", line 560, in <module>
    main(ApplicationCharm)
  File "/var/lib/juju/agents/unit-postgresql-test-app-0/charm/venv/lib/python3.10/site-packages/ops/__init__.py", line 356, in __call__
    return _main.main(charm_class=charm_class, use_juju_for_storage=use_juju_for_storage)
  File "/var/lib/juju/agents/unit-postgresql-test-app-0/charm/venv/lib/python3.10/site-packages/ops/_main.py", line 474, in main
    manager.run()
  File "/var/lib/juju/agents/unit-postgresql-test-app-0/charm/venv/lib/python3.10/site-packages/ops/_main.py", line 458, in run
    self._emit()
  File "/var/lib/juju/agents/unit-postgresql-test-app-0/charm/venv/lib/python3.10/site-packages/ops/_main.py", line 402, in _emit
    self._emit_charm_event(self.dispatcher.event_name)
  File "/var/lib/juju/agents/unit-postgresql-test-app-0/charm/venv/lib/python3.10/site-packages/ops/_main.py", line 437, in _emit_charm_event
    event_to_emit.emit(*args, **kwargs)
  File "/var/lib/juju/agents/unit-postgresql-test-app-0/charm/venv/lib/python3.10/site-packages/ops/framework.py", line 351, in emit
    framework._emit(event)
  File "/var/lib/juju/agents/unit-postgresql-test-app-0/charm/venv/lib/python3.10/site-packages/ops/framework.py", line 923, in _emit
    self._reemit(event_path)
  File "/var/lib/juju/agents/unit-postgresql-test-app-0/charm/venv/lib/python3.10/site-packages/ops/framework.py", line 1029, in _reemit
    custom_handler(event)
  File "/var/lib/juju/agents/unit-postgresql-test-app-0/charm/src/charm.py", line 485, in _on_run_sql_action
    connection = self.connect_to_database(
  File "/var/lib/juju/agents/unit-postgresql-test-app-0/charm/src/charm.py", line 554, in connect_to_database
    connection = psycopg2.connect(connstr)
  File "/var/lib/juju/agents/unit-postgresql-test-app-0/charm/venv/lib/python3.10/site-packages/psycopg2/__init__.py", line 122, in connect
    conn = _connect(dsn, connection_factory=connection_factory, **kwasync)
psycopg2.OperationalError: connection to server on socket "/var/snap/charmed-pgbouncer/current/run/pgbouncer/pgbouncer/instance_0/.s.PGSQL.6432" failed: FATAL:  server login has been failing, try again later (server_login_retry)

unit-postgresql-test-app-0: 01:58:51 ERROR unit.postgresql-test-app/0.juju-log Uncaught exception while in charm code:
Traceback (most recent call last):
  File "/var/lib/juju/agents/unit-postgresql-test-app-0/charm/src/charm.py", line 560, in <module>
    main(ApplicationCharm)
  File "/var/lib/juju/agents/unit-postgresql-test-app-0/charm/venv/lib/python3.10/site-packages/ops/__init__.py", line 356, in __call__
    return _main.main(charm_class=charm_class, use_juju_for_storage=use_juju_for_storage)
  File "/var/lib/juju/agents/unit-postgresql-test-app-0/charm/venv/lib/python3.10/site-packages/ops/_main.py", line 474, in main
    manager.run()
  File "/var/lib/juju/agents/unit-postgresql-test-app-0/charm/venv/lib/python3.10/site-packages/ops/_main.py", line 458, in run
    self._emit()
  File "/var/lib/juju/agents/unit-postgresql-test-app-0/charm/venv/lib/python3.10/site-packages/ops/_main.py", line 402, in _emit
    self._emit_charm_event(self.dispatcher.event_name)
  File "/var/lib/juju/agents/unit-postgresql-test-app-0/charm/venv/lib/python3.10/site-packages/ops/_main.py", line 437, in _emit_charm_event
    event_to_emit.emit(*args, **kwargs)
  File "/var/lib/juju/agents/unit-postgresql-test-app-0/charm/venv/lib/python3.10/site-packages/ops/framework.py", line 351, in emit
    framework._emit(event)
  File "/var/lib/juju/agents/unit-postgresql-test-app-0/charm/venv/lib/python3.10/site-packages/ops/framework.py", line 923, in _emit
    self._reemit(event_path)
  File "/var/lib/juju/agents/unit-postgresql-test-app-0/charm/venv/lib/python3.10/site-packages/ops/framework.py", line 1029, in _reemit
    custom_handler(event)
  File "/var/lib/juju/agents/unit-postgresql-test-app-0/charm/src/charm.py", line 485, in _on_run_sql_action
    connection = self.connect_to_database(
  File "/var/lib/juju/agents/unit-postgresql-test-app-0/charm/src/charm.py", line 554, in connect_to_database
    connection = psycopg2.connect(connstr)
  File "/var/lib/juju/agents/unit-postgresql-test-app-0/charm/venv/lib/python3.10/site-packages/psycopg2/__init__.py", line 122, in connect
    conn = _connect(dsn, connection_factory=connection_factory, **kwasync)
psycopg2.OperationalError: connection to server on socket "/var/snap/charmed-pgbouncer/current/run/pgbouncer/pgbouncer/instance_0/.s.PGSQL.6432" failed: FATAL:  server login has been failing, try again later (server_login_retry)

unit-postgresql-test-app-0: 01:58:53 ERROR unit.postgresql-test-app/0.juju-log Uncaught exception while in charm code:
Traceback (most recent call last):
  File "/var/lib/juju/agents/unit-postgresql-test-app-0/charm/src/charm.py", line 560, in <module>
    main(ApplicationCharm)
  File "/var/lib/juju/agents/unit-postgresql-test-app-0/charm/venv/lib/python3.10/site-packages/ops/__init__.py", line 356, in __call__
    return _main.main(charm_class=charm_class, use_juju_for_storage=use_juju_for_storage)
  File "/var/lib/juju/agents/unit-postgresql-test-app-0/charm/venv/lib/python3.10/site-packages/ops/_main.py", line 474, in main
    manager.run()
  File "/var/lib/juju/agents/unit-postgresql-test-app-0/charm/venv/lib/python3.10/site-packages/ops/_main.py", line 458, in run
    self._emit()
  File "/var/lib/juju/agents/unit-postgresql-test-app-0/charm/venv/lib/python3.10/site-packages/ops/_main.py", line 402, in _emit
    self._emit_charm_event(self.dispatcher.event_name)
  File "/var/lib/juju/agents/unit-postgresql-test-app-0/charm/venv/lib/python3.10/site-packages/ops/_main.py", line 437, in _emit_charm_event
    event_to_emit.emit(*args, **kwargs)
  File "/var/lib/juju/agents/unit-postgresql-test-app-0/charm/venv/lib/python3.10/site-packages/ops/framework.py", line 351, in emit
    framework._emit(event)
  File "/var/lib/juju/agents/unit-postgresql-test-app-0/charm/venv/lib/python3.10/site-packages/ops/framework.py", line 923, in _emit
    self._reemit(event_path)
  File "/var/lib/juju/agents/unit-postgresql-test-app-0/charm/venv/lib/python3.10/site-packages/ops/framework.py", line 1029, in _reemit
    custom_handler(event)
  File "/var/lib/juju/agents/unit-postgresql-test-app-0/charm/src/charm.py", line 485, in _on_run_sql_action
    connection = self.connect_to_database(
  File "/var/lib/juju/agents/unit-postgresql-test-app-0/charm/src/charm.py", line 554, in connect_to_database
    connection = psycopg2.connect(connstr)
  File "/var/lib/juju/agents/unit-postgresql-test-app-0/charm/venv/lib/python3.10/site-packages/psycopg2/__init__.py", line 122, in connect
    conn = _connect(dsn, connection_factory=connection_factory, **kwasync)
psycopg2.OperationalError: connection to server on socket "/var/snap/charmed-pgbouncer/current/run/pgbouncer/pgbouncer/instance_0/.s.PGSQL.6432" failed: FATAL:  server login has been failing, try again later (server_login_retry)

unit-postgresql-test-app-0: 01:58:55 ERROR unit.postgresql-test-app/0.juju-log Uncaught exception while in charm code:
Traceback (most recent call last):
  File "/var/lib/juju/agents/unit-postgresql-test-app-0/charm/src/charm.py", line 560, in <module>
    main(ApplicationCharm)
  File "/var/lib/juju/agents/unit-postgresql-test-app-0/charm/venv/lib/python3.10/site-packages/ops/__init__.py", line 356, in __call__
    return _main.main(charm_class=charm_class, use_juju_for_storage=use_juju_for_storage)
  File "/var/lib/juju/agents/unit-postgresql-test-app-0/charm/venv/lib/python3.10/site-packages/ops/_main.py", line 474, in main
    manager.run()
  File "/var/lib/juju/agents/unit-postgresql-test-app-0/charm/venv/lib/python3.10/site-packages/ops/_main.py", line 458, in run
    self._emit()
  File "/var/lib/juju/agents/unit-postgresql-test-app-0/charm/venv/lib/python3.10/site-packages/ops/_main.py", line 402, in _emit
    self._emit_charm_event(self.dispatcher.event_name)
  File "/var/lib/juju/agents/unit-postgresql-test-app-0/charm/venv/lib/python3.10/site-packages/ops/_main.py", line 437, in _emit_charm_event
    event_to_emit.emit(*args, **kwargs)
  File "/var/lib/juju/agents/unit-postgresql-test-app-0/charm/venv/lib/python3.10/site-packages/ops/framework.py", line 351, in emit
    framework._emit(event)
  File "/var/lib/juju/agents/unit-postgresql-test-app-0/charm/venv/lib/python3.10/site-packages/ops/framework.py", line 923, in _emit
    self._reemit(event_path)
  File "/var/lib/juju/agents/unit-postgresql-test-app-0/charm/venv/lib/python3.10/site-packages/ops/framework.py", line 1029, in _reemit
    custom_handler(event)
  File "/var/lib/juju/agents/unit-postgresql-test-app-0/charm/src/charm.py", line 485, in _on_run_sql_action
    connection = self.connect_to_database(
  File "/var/lib/juju/agents/unit-postgresql-test-app-0/charm/src/charm.py", line 554, in connect_to_database
    connection = psycopg2.connect(connstr)
  File "/var/lib/juju/agents/unit-postgresql-test-app-0/charm/venv/lib/python3.10/site-packages/psycopg2/__init__.py", line 122, in connect
    conn = _connect(dsn, connection_factory=connection_factory, **kwasync)
psycopg2.OperationalError: connection to server on socket "/var/snap/charmed-pgbouncer/current/run/pgbouncer/pgbouncer/instance_0/.s.PGSQL.6432" failed: FATAL:  server login has been failing, try again later (server_login_retry)

unit-postgresql-test-app-0: 01:58:57 ERROR unit.postgresql-test-app/0.juju-log Uncaught exception while in charm code:
Traceback (most recent call last):
  File "/var/lib/juju/agents/unit-postgresql-test-app-0/charm/src/charm.py", line 560, in <module>
    main(ApplicationCharm)
  File "/var/lib/juju/agents/unit-postgresql-test-app-0/charm/venv/lib/python3.10/site-packages/ops/__init__.py", line 356, in __call__
    return _main.main(charm_class=charm_class, use_juju_for_storage=use_juju_for_storage)
  File "/var/lib/juju/agents/unit-postgresql-test-app-0/charm/venv/lib/python3.10/site-packages/ops/_main.py", line 474, in main
    manager.run()
  File "/var/lib/juju/agents/unit-postgresql-test-app-0/charm/venv/lib/python3.10/site-packages/ops/_main.py", line 458, in run
    self._emit()
  File "/var/lib/juju/agents/unit-postgresql-test-app-0/charm/venv/lib/python3.10/site-packages/ops/_main.py", line 402, in _emit
    self._emit_charm_event(self.dispatcher.event_name)
  File "/var/lib/juju/agents/unit-postgresql-test-app-0/charm/venv/lib/python3.10/site-packages/ops/_main.py", line 437, in _emit_charm_event
    event_to_emit.emit(*args, **kwargs)
  File "/var/lib/juju/agents/unit-postgresql-test-app-0/charm/venv/lib/python3.10/site-packages/ops/framework.py", line 351, in emit
    framework._emit(event)
  File "/var/lib/juju/agents/unit-postgresql-test-app-0/charm/venv/lib/python3.10/site-packages/ops/framework.py", line 923, in _emit
    self._reemit(event_path)
  File "/var/lib/juju/agents/unit-postgresql-test-app-0/charm/venv/lib/python3.10/site-packages/ops/framework.py", line 1029, in _reemit
    custom_handler(event)
  File "/var/lib/juju/agents/unit-postgresql-test-app-0/charm/src/charm.py", line 485, in _on_run_sql_action
    connection = self.connect_to_database(
  File "/var/lib/juju/agents/unit-postgresql-test-app-0/charm/src/charm.py", line 554, in connect_to_database
    connection = psycopg2.connect(connstr)
  File "/var/lib/juju/agents/unit-postgresql-test-app-0/charm/venv/lib/python3.10/site-packages/psycopg2/__init__.py", line 122, in connect
    conn = _connect(dsn, connection_factory=connection_factory, **kwasync)
psycopg2.OperationalError: connection to server on socket "/var/snap/charmed-pgbouncer/current/run/pgbouncer/pgbouncer/instance_0/.s.PGSQL.6432" failed: FATAL:  server login has been failing, try again later (server_login_retry)

machine-4: 01:59:55 ERROR juju.worker.dependency "kvm-container-provisioner" manifold worker returned unexpected error: container types not yet available
machine-4: 01:59:55 ERROR juju.worker.dependency "lxd-container-provisioner" manifold worker returned unexpected error: container types not yet available
unit-another-application-0: 01:59:55 ERROR juju.worker.meterstatus error running "meter-status-changed": charm missing from disk
machine-5: 02:01:59 ERROR juju.worker.dependency "kvm-container-provisioner" manifold worker returned unexpected error: container types not yet available
machine-5: 02:01:59 ERROR juju.worker.dependency "lxd-container-provisioner" manifold worker returned unexpected error: container types not yet available
unit-another-postgresql-0: 02:01:59 ERROR juju.worker.meterstatus error running "meter-status-changed": charm missing from disk
machine-6: 02:02:10 ERROR juju.worker.dependency "kvm-container-provisioner" manifold worker returned unexpected error: container types not yet available
machine-6: 02:02:10 ERROR juju.worker.dependency "lxd-container-provisioner" manifold worker returned unexpected error: container types not yet available
unit-another-postgresql-1: 02:02:10 ERROR juju.worker.meterstatus error running "meter-status-changed": charm missing from disk
unit-another-postgresql-0: 02:02:38 ERROR unit.another-postgresql/0.juju-log Unable to get the state of the cluster
Traceback (most recent call last):
  File "/var/lib/juju/agents/unit-another-postgresql-0/charm/venv/lib/python3.10/site-packages/urllib3/connection.py", line 198, in _new_conn
    sock = connection.create_connection(
  File "/var/lib/juju/agents/unit-another-postgresql-0/charm/venv/lib/python3.10/site-packages/urllib3/util/connection.py", line 85, in create_connection
    raise err
  File "/var/lib/juju/agents/unit-another-postgresql-0/charm/venv/lib/python3.10/site-packages/urllib3/util/connection.py", line 73, in create_connection
    sock.connect(sa)
ConnectionRefusedError: [Errno 111] Connection refused

The above exception was the direct cause of the following exception:

Traceback (most recent call last):
  File "/var/lib/juju/agents/unit-another-postgresql-0/charm/venv/lib/python3.10/site-packages/urllib3/connectionpool.py", line 787, in urlopen
    response = self._make_request(
  File "/var/lib/juju/agents/unit-another-postgresql-0/charm/venv/lib/python3.10/site-packages/urllib3/connectionpool.py", line 493, in _make_request
    conn.request(
  File "/var/lib/juju/agents/unit-another-postgresql-0/charm/venv/lib/python3.10/site-packages/urllib3/connection.py", line 445, in request
    self.endheaders()
  File "/usr/lib/python3.10/http/client.py", line 1278, in endheaders
    self._send_output(message_body, encode_chunked=encode_chunked)
  File "/usr/lib/python3.10/http/client.py", line 1038, in _send_output
    self.send(msg)
  File "/usr/lib/python3.10/http/client.py", line 976, in send
    self.connect()
  File "/var/lib/juju/agents/unit-another-postgresql-0/charm/venv/lib/python3.10/site-packages/urllib3/connection.py", line 276, in connect
    self.sock = self._new_conn()
  File "/var/lib/juju/agents/unit-another-postgresql-0/charm/venv/lib/python3.10/site-packages/urllib3/connection.py", line 213, in _new_conn
    raise NewConnectionError(
urllib3.exceptions.NewConnectionError: <urllib3.connection.HTTPConnection object at 0x7fe8fe1179a0>: Failed to establish a new connection: [Errno 111] Connection refused

The above exception was the direct cause of the following exception:

Traceback (most recent call last):
  File "/var/lib/juju/agents/unit-another-postgresql-0/charm/venv/lib/python3.10/site-packages/requests/adapters.py", line 667, in send
    resp = conn.urlopen(
  File "/var/lib/juju/agents/unit-another-postgresql-0/charm/venv/lib/python3.10/site-packages/urllib3/connectionpool.py", line 841, in urlopen
    retries = retries.increment(
  File "/var/lib/juju/agents/unit-another-postgresql-0/charm/venv/lib/python3.10/site-packages/urllib3/util/retry.py", line 519, in increment
    raise MaxRetryError(_pool, url, reason) from reason  # type: ignore[arg-type]
urllib3.exceptions.MaxRetryError: HTTPConnectionPool(host='10.7.81.55', port=8008): Max retries exceeded with url: /cluster (Caused by NewConnectionError('<urllib3.connection.HTTPConnection object at 0x7fe8fe1179a0>: Failed to establish a new connection: [Errno 111] Connection refused'))

During handling of the above exception, another exception occurred:

Traceback (most recent call last):
  File "/var/lib/juju/agents/unit-another-postgresql-0/charm/src/cluster.py", line 568, in are_replicas_up
    response = requests.get(
  File "/var/lib/juju/agents/unit-another-postgresql-0/charm/venv/lib/python3.10/site-packages/requests/api.py", line 73, in get
    return request("get", url, params=params, **kwargs)
  File "/var/lib/juju/agents/unit-another-postgresql-0/charm/venv/lib/python3.10/site-packages/requests/api.py", line 59, in request
    return session.request(method=method, url=url, **kwargs)
  File "/var/lib/juju/agents/unit-another-postgresql-0/charm/venv/lib/python3.10/site-packages/requests/sessions.py", line 589, in request
    resp = self.send(prep, **send_kwargs)
  File "/var/lib/juju/agents/unit-another-postgresql-0/charm/venv/lib/python3.10/site-packages/requests/sessions.py", line 703, in send
    r = adapter.send(request, **kwargs)
  File "/var/lib/juju/agents/unit-another-postgresql-0/charm/venv/lib/python3.10/site-packages/requests/adapters.py", line 700, in send
    raise ConnectionError(e, request=request)
requests.exceptions.ConnectionError: HTTPConnectionPool(host='10.7.81.55', port=8008): Max retries exceeded with url: /cluster (Caused by NewConnectionError('<urllib3.connection.HTTPConnection object at 0x7fe8fe1179a0>: Failed to establish a new connection: [Errno 111] Connection refused'))
unit-postgresql-0: 02:02:41 ERROR juju.worker.dependency "log-sender" manifold worker returned unexpected error: sending log message: websocket: close 1005 (no status): websocket: close sent
unit-postgresql-test-app-1: 02:02:42 ERROR juju.worker.dependency "log-sender" manifold worker returned unexpected error: sending log message: websocket: close 1005 (no status): websocket: close sent
unit-postgresql-1: 02:02:45 ERROR juju.worker.dependency "log-sender" manifold worker returned unexpected error: sending log message: websocket: close 1005 (no status): websocket: close sent
unit-another-application-0: 02:02:48 ERROR juju.worker.dependency "log-sender" manifold worker returned unexpected error: sending log message: websocket: close 1005 (no status): websocket: close sent
unit-postgresql-test-app-0: 02:02:48 ERROR juju.worker.dependency "log-sender" manifold worker returned unexpected error: sending log message: websocket: close 1005 (no status): websocket: close sent
unit-another-postgresql-0: 02:04:18 ERROR juju.worker.dependency "log-sender" manifold worker returned unexpected error: sending log message: websocket: close 1005 (no status): websocket: close sent
unit-another-postgresql-1: 02:04:30 ERROR juju.worker.dependency "log-sender" manifold worker returned unexpected error: sending log message: websocket: close 1005 (no status): websocket: close sent
unit-postgresql-1: 02:06:38 ERROR juju.worker.dependency "log-sender" manifold worker returned unexpected error: sending log message: websocket: close 1005 (no status): websocket: close sent
unit-another-postgresql-0: 02:08:01 ERROR juju.worker.dependency "log-sender" manifold worker returned unexpected error: sending log message: websocket: close 1005 (no status): websocket: close sent
unit-postgresql-0: 02:08:57 ERROR juju.worker.dependency "log-sender" manifold worker returned unexpected error: sending log message: websocket: close 1005 (no status): websocket: close sent
machine-0: 02:09:52 ERROR juju.worker.dependency "log-sender" manifold worker returned unexpected error: sending log message: websocket: close 1005 (no status): websocket: close sent
machine-3: 02:09:52 ERROR juju.worker.dependency "log-sender" manifold worker returned unexpected error: sending log message: websocket: close 1005 (no status): websocket: close sent
unit-pgbouncer-2: 02:09:54 ERROR juju.worker.meterstatus error running "meter-status-changed": charm missing from disk
unit-pgbouncer-3: 02:09:54 ERROR juju.worker.meterstatus error running "meter-status-changed": charm missing from disk
unit-another-pgbouncer-0: 02:09:56 ERROR juju.worker.meterstatus error running "meter-status-changed": charm missing from disk
unit-another-pgbouncer-1: 02:09:56 ERROR juju.worker.meterstatus error running "meter-status-changed": exit status 1
unit-another-postgresql-1: 02:12:29 ERROR juju.worker.dependency "log-sender" manifold worker returned unexpected error: sending log message: websocket: close 1005 (no status): websocket: close sent
unit-another-postgresql-0: 02:12:51 ERROR juju.worker.dependency "log-sender" manifold worker returned unexpected error: sending log message: websocket: close 1005 (no status): websocket: close sent
machine-1: 02:13:13 ERROR juju.worker.dependency "log-sender" manifold worker returned unexpected error: sending log message: websocket: close 1005 (no status): websocket: close sent
machine-2: 02:13:13 ERROR juju.worker.dependency "log-sender" manifold worker returned unexpected error: sending log message: websocket: close 1005 (no status): websocket: close sent
machine-6: 02:13:14 ERROR juju.worker.dependency "log-sender" manifold worker returned unexpected error: sending log message: websocket: close 1005 (no status): websocket: close sent
machine-4: 02:13:14 ERROR juju.worker.dependency "log-sender" manifold worker returned unexpected error: sending log message: websocket: close 1005 (no status): websocket: close sent
machine-5: 02:13:14 ERROR juju.worker.dependency "log-sender" manifold worker returned unexpected error: sending log message: websocket: close 1005 (no status): websocket: close sent
unit-pgbouncer-4: 02:13:17 ERROR juju.worker.meterstatus error running "meter-status-changed": charm missing from disk
unit-pgbouncer-5: 02:13:17 ERROR juju.worker.meterstatus error running "meter-status-changed": charm missing from disk
unit-another-pgbouncer-2: 02:13:19 ERROR juju.worker.meterstatus error running "meter-status-changed": exit status 1
unit-another-pgbouncer-3: 02:13:19 ERROR juju.worker.meterstatus error running "meter-status-changed": exit status 1
unit-postgresql-1: 02:13:35 ERROR juju.worker.dependency "log-sender" manifold worker returned unexpected error: sending log message: websocket: close 1005 (no status): websocket: close sent
unit-pgbouncer-5: 02:14:58 ERROR juju.worker.dependency "log-sender" manifold worker returned unexpected error: sending log message: websocket: close 1005 (no status): websocket: close sent
unit-pgbouncer-4: 02:14:59 ERROR juju.worker.dependency "log-sender" manifold worker returned unexpected error: sending log message: websocket: close 1005 (no status): websocket: close sent
unit-another-pgbouncer-3: 02:15:00 ERROR juju.worker.dependency "log-sender" manifold worker returned unexpected error: sending log message: websocket: close 1005 (no status): websocket: close sent
unit-another-pgbouncer-2: 02:15:02 ERROR juju.worker.dependency "log-sender" manifold worker returned unexpected error: sending log message: websocket: close 1005 (no status): websocket: close sent
unit-postgresql-0: 02:15:09 ERROR juju.worker.dependency "log-sender" manifold worker returned unexpected error: sending log message: websocket: close 1005 (no status): websocket: close sent
machine-4: 02:16:28 ERROR juju.worker.dependency "log-sender" manifold worker returned unexpected error: sending log message: websocket: close 1005 (no status): websocket: close sent
machine-6: 02:16:28 ERROR juju.worker.dependency "log-sender" manifold worker returned unexpected error: sending log message: websocket: close 1005 (no status): websocket: close sent
machine-1: 02:16:28 ERROR juju.worker.dependency "log-sender" manifold worker returned unexpected error: sending log message: websocket: close 1005 (no status): websocket: close sent
machine-2: 02:16:28 ERROR juju.worker.dependency "log-sender" manifold worker returned unexpected error: sending log message: websocket: close 1005 (no status): websocket: close sent
machine-5: 02:16:28 ERROR juju.worker.dependency "log-sender" manifold worker returned unexpected error: sending log message: websocket: close 1005 (no status): websocket: close sent
unit-another-postgresql-0: 02:16:49 ERROR juju.worker.dependency "log-sender" manifold worker returned unexpected error: sending log message: websocket: close 1005 (no status): websocket: close sent

[32mINFO    [0m pytest_operator.plugin:plugin.py:1025 Forgetting model main...