[32mINFO    [0m pytest_operator.plugin:plugin.py:951 Model status:

Model    Controller     Cloud/Region         Version  SLA          Timestamp
testing  concierge-lxd  localhost/localhost  3.6.10   unsupported  01:50:21Z

App                  Version  Status   Scale  Charm                Channel      Rev  Exposed  Message
pgbouncer            1.21.0   error        3  pgbouncer            1/edge       846  no       hook failed: "backend-database-relation-changed"
postgresql           14.19    waiting      3  postgresql           14/edge      913  no       awaiting for cluster to start
postgresql-test-app           blocked      3  postgresql-test-app  latest/edge  406  no       No database integration available

Unit                    Workload     Agent      Machine  Public address  Ports     Message
postgresql-test-app/0*  blocked      idle       0        10.63.49.112              No database integration available
  pgbouncer/0*          error        idle                10.63.49.112              hook failed: "backend-database-relation-changed"
postgresql-test-app/1   blocked      idle       1        10.63.49.53               No database integration available
  pgbouncer/1           maintenance  executing           10.63.49.53               updating PgBouncer config
postgresql-test-app/2   blocked      idle       2        10.63.49.223              No database integration available
  pgbouncer/2           maintenance  executing           10.63.49.223              Reloading Pgbouncer
postgresql/0            waiting      executing  3        10.63.49.79     5432/tcp  awaiting for cluster to start
postgresql/1*           active       executing  4        10.63.49.72     5432/tcp  Primary (degraded)
postgresql/2            waiting      executing  5        10.63.49.62     5432/tcp  awaiting for cluster to start

Machine  State    Address       Inst id        Base          AZ             Message
0        started  10.63.49.112  juju-527e82-0  ubuntu@22.04  runnervm3ublj  Running
1        started  10.63.49.53   juju-527e82-1  ubuntu@22.04  runnervm3ublj  Running
2        started  10.63.49.223  juju-527e82-2  ubuntu@22.04  runnervm3ublj  Running
3        started  10.63.49.79   juju-527e82-3  ubuntu@22.04  runnervm3ublj  Running
4        started  10.63.49.72   juju-527e82-4  ubuntu@22.04  runnervm3ublj  Running
5        started  10.63.49.62   juju-527e82-5  ubuntu@22.04  runnervm3ublj  Running

[32mINFO    [0m pytest_operator.plugin:plugin.py:957 Juju error logs:

machine-0: 01:44:38 ERROR juju.worker.dependency "kvm-container-provisioner" manifold worker returned unexpected error: container types not yet available
machine-0: 01:44:38 ERROR juju.worker.dependency "lxd-container-provisioner" manifold worker returned unexpected error: container types not yet available
machine-4: 01:47:34 ERROR juju.worker.dependency "lxd-container-provisioner" manifold worker returned unexpected error: container types not yet available
machine-4: 01:47:34 ERROR juju.worker.dependency "kvm-container-provisioner" manifold worker returned unexpected error: container types not yet available
machine-5: 01:47:47 ERROR juju.worker.dependency "lxd-container-provisioner" manifold worker returned unexpected error: container types not yet available
machine-5: 01:47:47 ERROR juju.worker.dependency "kvm-container-provisioner" manifold worker returned unexpected error: container types not yet available
machine-3: 01:48:17 ERROR juju.worker.dependency "lxd-container-provisioner" manifold worker returned unexpected error: container types not yet available
machine-3: 01:48:17 ERROR juju.worker.dependency "kvm-container-provisioner" manifold worker returned unexpected error: container types not yet available
machine-1: 01:48:42 ERROR juju.worker.dependency "kvm-container-provisioner" manifold worker returned unexpected error: container types not yet available
machine-1: 01:48:42 ERROR juju.worker.dependency "lxd-container-provisioner" manifold worker returned unexpected error: container types not yet available
unit-postgresql-1: 01:49:00 ERROR unit.postgresql/1.juju-log Unable to get the state of the cluster
Traceback (most recent call last):
  File "/var/lib/juju/agents/unit-postgresql-1/charm/venv/lib/python3.10/site-packages/urllib3/connection.py", line 198, in _new_conn
    sock = connection.create_connection(
  File "/var/lib/juju/agents/unit-postgresql-1/charm/venv/lib/python3.10/site-packages/urllib3/util/connection.py", line 85, in create_connection
    raise err
  File "/var/lib/juju/agents/unit-postgresql-1/charm/venv/lib/python3.10/site-packages/urllib3/util/connection.py", line 73, in create_connection
    sock.connect(sa)
ConnectionRefusedError: [Errno 111] Connection refused

The above exception was the direct cause of the following exception:

Traceback (most recent call last):
  File "/var/lib/juju/agents/unit-postgresql-1/charm/venv/lib/python3.10/site-packages/urllib3/connectionpool.py", line 787, in urlopen
    response = self._make_request(
  File "/var/lib/juju/agents/unit-postgresql-1/charm/venv/lib/python3.10/site-packages/urllib3/connectionpool.py", line 493, in _make_request
    conn.request(
  File "/var/lib/juju/agents/unit-postgresql-1/charm/venv/lib/python3.10/site-packages/urllib3/connection.py", line 494, in request
    self.endheaders()
  File "/usr/lib/python3.10/http/client.py", line 1278, in endheaders
    self._send_output(message_body, encode_chunked=encode_chunked)
  File "/usr/lib/python3.10/http/client.py", line 1038, in _send_output
    self.send(msg)
  File "/usr/lib/python3.10/http/client.py", line 976, in send
    self.connect()
  File "/var/lib/juju/agents/unit-postgresql-1/charm/venv/lib/python3.10/site-packages/urllib3/connection.py", line 325, in connect
    self.sock = self._new_conn()
  File "/var/lib/juju/agents/unit-postgresql-1/charm/venv/lib/python3.10/site-packages/urllib3/connection.py", line 213, in _new_conn
    raise NewConnectionError(
urllib3.exceptions.NewConnectionError: <urllib3.connection.HTTPConnection object at 0x7f69165727a0>: Failed to establish a new connection: [Errno 111] Connection refused

The above exception was the direct cause of the following exception:

Traceback (most recent call last):
  File "/var/lib/juju/agents/unit-postgresql-1/charm/venv/lib/python3.10/site-packages/requests/adapters.py", line 644, in send
    resp = conn.urlopen(
  File "/var/lib/juju/agents/unit-postgresql-1/charm/venv/lib/python3.10/site-packages/urllib3/connectionpool.py", line 841, in urlopen
    retries = retries.increment(
  File "/var/lib/juju/agents/unit-postgresql-1/charm/venv/lib/python3.10/site-packages/urllib3/util/retry.py", line 519, in increment
    raise MaxRetryError(_pool, url, reason) from reason  # type: ignore[arg-type]
urllib3.exceptions.MaxRetryError: HTTPConnectionPool(host='10.63.49.72', port=8008): Max retries exceeded with url: /cluster (Caused by NewConnectionError('<urllib3.connection.HTTPConnection object at 0x7f69165727a0>: Failed to establish a new connection: [Errno 111] Connection refused'))

During handling of the above exception, another exception occurred:

Traceback (most recent call last):
  File "/var/lib/juju/agents/unit-postgresql-1/charm/src/cluster.py", line 577, in are_replicas_up
    response = requests.get(
  File "/var/lib/juju/agents/unit-postgresql-1/charm/venv/lib/python3.10/site-packages/requests/api.py", line 73, in get
    return request("get", url, params=params, **kwargs)
  File "/var/lib/juju/agents/unit-postgresql-1/charm/venv/lib/python3.10/site-packages/requests/api.py", line 59, in request
    return session.request(method=method, url=url, **kwargs)
  File "/var/lib/juju/agents/unit-postgresql-1/charm/venv/lib/python3.10/site-packages/requests/sessions.py", line 589, in request
    resp = self.send(prep, **send_kwargs)
  File "/var/lib/juju/agents/unit-postgresql-1/charm/venv/lib/python3.10/site-packages/requests/sessions.py", line 703, in send
    r = adapter.send(request, **kwargs)
  File "/var/lib/juju/agents/unit-postgresql-1/charm/venv/lib/python3.10/site-packages/requests/adapters.py", line 677, in send
    raise ConnectionError(e, request=request)
requests.exceptions.ConnectionError: HTTPConnectionPool(host='10.63.49.72', port=8008): Max retries exceeded with url: /cluster (Caused by NewConnectionError('<urllib3.connection.HTTPConnection object at 0x7f69165727a0>: Failed to establish a new connection: [Errno 111] Connection refused'))
machine-2: 01:49:14 ERROR juju.worker.dependency "lxd-container-provisioner" manifold worker returned unexpected error: container types not yet available
machine-2: 01:49:14 ERROR juju.worker.dependency "kvm-container-provisioner" manifold worker returned unexpected error: container types not yet available
unit-postgresql-1: 01:49:26 ERROR unit.postgresql/1.juju-log Failed to list PostgreSQL database users: could not translate host name "None" to address: Temporary failure in name resolution

unit-postgresql-1: 01:49:33 ERROR unit.postgresql/1.juju-log database:6: Failed to list PostgreSQL database users: could not translate host name "None" to address: Temporary failure in name resolution

unit-pgbouncer-0: 01:50:18 ERROR unit.pgbouncer/0.juju-log backend-database:6: Uncaught exception while in charm code:
Traceback (most recent call last):
  File "/var/lib/juju/agents/unit-pgbouncer-0/charm/src/charm.py", line 1024, in <module>
    main(PgBouncerCharm)
  File "/var/lib/juju/agents/unit-pgbouncer-0/charm/venv/lib/python3.10/site-packages/ops/__init__.py", line 356, in __call__
    return _main.main(charm_class=charm_class, use_juju_for_storage=use_juju_for_storage)
  File "/var/lib/juju/agents/unit-pgbouncer-0/charm/venv/lib/python3.10/site-packages/ops/_main.py", line 502, in main
    manager.run()
  File "/var/lib/juju/agents/unit-pgbouncer-0/charm/venv/lib/python3.10/site-packages/ops/_main.py", line 486, in run
    self._emit()
  File "/var/lib/juju/agents/unit-pgbouncer-0/charm/venv/lib/python3.10/site-packages/ops/_main.py", line 421, in _emit
    self._emit_charm_event(self.dispatcher.event_name)
  File "/var/lib/juju/agents/unit-pgbouncer-0/charm/venv/lib/python3.10/site-packages/ops/_main.py", line 465, in _emit_charm_event
    event_to_emit.emit(*args, **kwargs)
  File "/var/lib/juju/agents/unit-pgbouncer-0/charm/venv/lib/python3.10/site-packages/ops/framework.py", line 351, in emit
    framework._emit(event)
  File "/var/lib/juju/agents/unit-pgbouncer-0/charm/venv/lib/python3.10/site-packages/ops/framework.py", line 924, in _emit
    self._reemit(event_path)
  File "/var/lib/juju/agents/unit-pgbouncer-0/charm/venv/lib/python3.10/site-packages/ops/framework.py", line 1030, in _reemit
    custom_handler(event)
  File "/var/lib/juju/agents/unit-pgbouncer-0/charm/lib/charms/data_platform_libs/v0/data_interfaces.py", line 3625, in _on_relation_changed_event
    getattr(self.on, "database_created").emit(
  File "/var/lib/juju/agents/unit-pgbouncer-0/charm/venv/lib/python3.10/site-packages/ops/framework.py", line 351, in emit
    framework._emit(event)
  File "/var/lib/juju/agents/unit-pgbouncer-0/charm/venv/lib/python3.10/site-packages/ops/framework.py", line 924, in _emit
    self._reemit(event_path)
  File "/var/lib/juju/agents/unit-pgbouncer-0/charm/venv/lib/python3.10/site-packages/ops/framework.py", line 1030, in _reemit
    custom_handler(event)
  File "/var/lib/juju/agents/unit-pgbouncer-0/charm/lib/charms/tempo_coordinator_k8s/v0/charm_tracing.py", line 1146, in wrapped_function
    return callable(*args, **kwargs)  # type: ignore
  File "/var/lib/juju/agents/unit-pgbouncer-0/charm/src/relations/backend_database.py", line 240, in _on_database_created
    self.initialise_auth_function(self.collect_databases())
  File "/var/lib/juju/agents/unit-pgbouncer-0/charm/lib/charms/tempo_coordinator_k8s/v0/charm_tracing.py", line 1146, in wrapped_function
    return callable(*args, **kwargs)  # type: ignore
  File "/var/lib/juju/agents/unit-pgbouncer-0/charm/src/relations/backend_database.py", line 376, in initialise_auth_function
    with self.postgres._connect_to_database(dbname) as conn, conn.cursor() as cursor:
  File "/var/lib/juju/agents/unit-pgbouncer-0/charm/lib/charms/postgresql_k8s/v0/postgresql.py", line 184, in _connect_to_database
    connection = psycopg2.connect(
  File "/var/lib/juju/agents/unit-pgbouncer-0/charm/venv/lib/python3.10/site-packages/psycopg2/__init__.py", line 122, in connect
    conn = _connect(dsn, connection_factory=connection_factory, **kwasync)
psycopg2.OperationalError: connection to server at "10.63.49.72", port 5432 failed: FATAL:  no pg_hba.conf entry for host "10.63.49.112", user "relation-6", database "postgres", no encryption

unit-pgbouncer-0: 01:50:18 ERROR juju.worker.uniter.operation hook "backend-database-relation-changed" (via hook dispatching script: dispatch) failed: exit status 1

[32mINFO    [0m pytest_operator.plugin:plugin.py:1039 Forgetting model main...