[32mINFO    [0m root:helpers.py:96 (0, '{"pgbouncer/5":{"workload-version":"1.21.0","machine":"3","opened-ports":null,"public-address":"10.173.132.161","charm":"local:jammy/pgbouncer-0","leader":true,"life":"alive","relation-info":[{"relation-id":6,"endpoint":"backend-database","related-endpoint":"database","application-data":{"data":"{\\"database\\": \\"pgbouncer\\", \\"extra-user-roles\\": \\"SUPERUSER\\", \\"requested-secrets\\": \\"[\\\\\\"username\\\\\\", \\\\\\"password\\\\\\", \\\\\\"tls\\\\\\", \\\\\\"tls-ca\\\\\\", \\\\\\"uris\\\\\\"]\\"}","database":"pgbouncer","endpoints":"10.173.132.229:5432","read-only-endpoints":"10.173.132.158:5432","secret-tls":"secret://d5a218f5-db3c-45cb-8293-98f080a69a7f/cuddh25kisjt5ag6dnb0","secret-user":"secret://d5a218f5-db3c-45cb-8293-98f080a69a7f/cuddh1tkisjt5ag6dnag","version":"14.15"},"local-unit":{"in-scope":false,"data":null},"related-units":{"postgresql/0":{"in-scope":true,"data":{"egress-subnets":"10.173.132.229/32","ingress-address":"10.173.132.229","private-address":"10.173.132.229"}},"postgresql/1":{"in-scope":true,"data":{"egress-subnets":"10.173.132.158/32","ingress-address":"10.173.132.158","private-address":"10.173.132.158"}}}},{"relation-id":17,"endpoint":"database","related-endpoint":"database","application-data":{"database":"postgresql_test_app_database","extra-user-roles":"CREATEDB,CREATEROLE","requested-secrets":"[\\"username\\", \\"password\\", \\"tls\\", \\"tls-ca\\", \\"uris\\"]"},"local-unit":{"in-scope":false,"data":null},"related-units":{"postgresql-test-app/1":{"in-scope":true,"data":{"data":"{\\"database\\": \\"postgresql_test_app_database\\", \\"endpoints\\": \\"localhost:6432\\", \\"secret-user\\": \\"secret://d5a218f5-db3c-45cb-8293-98f080a69a7f/cuddpctkisjt5ag6dng0\\", \\"subordinated\\": \\"true\\", \\"version\\": \\"14.15\\"}","egress-subnets":"10.173.132.161/32","ingress-address":"10.173.132.161","private-address":"10.173.132.161"}},"postgresql-test-app/2":{"in-scope":true,"data":{"data":"{\\"database\\": \\"postgresql_test_app_database\\", \\"endpoints\\": \\"localhost:6432\\", \\"secret-user\\": \\"secret://d5a218f5-db3c-45cb-8293-98f080a69a7f/cuddpctkisjt5ag6dng0\\", \\"subordinated\\": \\"true\\", \\"version\\": \\"14.15\\"}","egress-subnets":"10.173.132.94/32","ingress-address":"10.173.132.94","private-address":"10.173.132.94"}}}},{"relation-id":5,"endpoint":"pgb-peers","related-endpoint":"pgb-peers","application-data":{"current_port":"6432","leader_ip":"10.173.132.161","pgb_dbs_config":"{\\"17\\": {\\"name\\": \\"postgresql_test_app_database\\", \\"legacy\\": false}, \\"*\\": {\\"name\\": \\"*\\", \\"auth_dbname\\": \\"postgresql_test_app_database\\"}}","readonly_dbs":"[\\"another_database\\", \\"postgresql_test_app_multiple_database_clusters\\"]"},"local-unit":{"in-scope":true,"data":{"auth_file_set":"true","egress-subnets":"10.173.132.161/32","ingress-address":"10.173.132.161","pgb_dbs":"3f7f43cebb47d7003b9dfaa7213fd98c","private-address":"10.173.132.161"}},"related-units":{"pgbouncer/9":{"in-scope":true,"data":{"auth_file_set":"true","egress-subnets":"10.173.132.94/32","ingress-address":"10.173.132.94","pgb_dbs":"3f7f43cebb47d7003b9dfaa7213fd98c","private-address":"10.173.132.94"}}}},{"relation-id":4,"endpoint":"upgrade","related-endpoint":"upgrade","application-data":{"dependencies":"{\\"charm\\": {\\"dependencies\\": {}, \\"name\\": \\"pgbouncer\\", \\"upgrade_supported\\": \\"\\u003e0\\", \\"version\\": \\"1\\"}, \\"snap\\": {\\"dependencies\\": {}, \\"name\\": \\"charmed-postgresql\\", \\"upgrade_supported\\": \\"^1\\", \\"version\\": \\"1.18.0\\"}}"},"local-unit":{"in-scope":true,"data":{"egress-subnets":"10.173.132.161/32","ingress-address":"10.173.132.161","private-address":"10.173.132.161","state":"idle"}},"related-units":{"pgbouncer/9":{"in-scope":true,"data":{"egress-subnets":"10.173.132.94/32","ingress-address":"10.173.132.94","private-address":"10.173.132.94","state":"idle"}}}}]}}\n', '')
[32mINFO    [0m juju.model:model.py:2972 Waiting for model:
  postgresql-test-app/1 [executing] active: received database credentials of the first database
  postgresql-test-app/2 [executing] active: received database credentials of the first database
  postgresql/0 [executing] active: Primary
  postgresql/1 [executing] active:
[32mINFO    [0m pytest_operator.plugin:plugin.py:929 Model status:

Model  Controller           Cloud/Region         Version  SLA          Timestamp
test   localhost-localhost  localhost/localhost  3.6.2    unsupported  02:06:55Z

App                  Version  Status   Scale  Charm                Channel      Rev  Exposed  Message
another-application           active       1  postgresql-test-app  latest/edge  344  no       
another-pgbouncer    1.21.0   active       2  pgbouncer                           1  no       
another-postgresql   14.15    active       2  postgresql           14/edge      553  no       
pgbouncer                     unknown      0  pgbouncer                           0  no       
postgresql           14.15    active       2  postgresql           14/edge      553  no       
postgresql-test-app           active       2  postgresql-test-app  latest/edge  344  no       

Unit                    Workload  Agent  Machine  Public address  Ports     Message
another-application/0*  active    idle   4        10.173.132.22             
another-postgresql/0    active    idle   5        10.173.132.171  5432/tcp  
another-postgresql/1*   active    idle   6        10.173.132.182  5432/tcp  Primary
postgresql-test-app/1*  active    idle   3        10.173.132.161            
  another-pgbouncer/3*  active    idle            10.173.132.161            
postgresql-test-app/2   active    idle   7        10.173.132.94             
  another-pgbouncer/9   active    idle            10.173.132.94             
postgresql/0*           active    idle   1        10.173.132.229  5432/tcp  Primary
postgresql/1            active    idle   2        10.173.132.158  5432/tcp  

Machine  State    Address         Inst id        Base          AZ  Message
1        started  10.173.132.229  juju-a69a7f-1  ubuntu@22.04      Running
2        started  10.173.132.158  juju-a69a7f-2  ubuntu@22.04      Running
3        started  10.173.132.161  juju-a69a7f-3  ubuntu@22.04      Running
4        started  10.173.132.22   juju-a69a7f-4  ubuntu@22.04      Running
5        started  10.173.132.171  juju-a69a7f-5  ubuntu@22.04      Running
6        started  10.173.132.182  juju-a69a7f-6  ubuntu@22.04      Running
7        started  10.173.132.94   juju-a69a7f-7  ubuntu@22.04      Running

[32mINFO    [0m pytest_operator.plugin:plugin.py:935 Juju error logs:

machine-1: 01:33:22 ERROR juju.worker.dependency "kvm-container-provisioner" manifold worker returned unexpected error: container types not yet available
machine-1: 01:33:22 ERROR juju.worker.dependency "lxd-container-provisioner" manifold worker returned unexpected error: container types not yet available
unit-postgresql-0: 01:33:22 ERROR juju.worker.meterstatus error running "meter-status-changed": charm missing from disk
machine-2: 01:33:27 ERROR juju.worker.dependency "lxd-container-provisioner" manifold worker returned unexpected error: container types not yet available
machine-2: 01:33:27 ERROR juju.worker.dependency "kvm-container-provisioner" manifold worker returned unexpected error: container types not yet available
unit-postgresql-1: 01:33:27 ERROR juju.worker.meterstatus error running "meter-status-changed": charm missing from disk
machine-0: 01:33:27 ERROR juju.worker.dependency "lxd-container-provisioner" manifold worker returned unexpected error: container types not yet available
machine-0: 01:33:27 ERROR juju.worker.dependency "kvm-container-provisioner" manifold worker returned unexpected error: container types not yet available
unit-postgresql-test-app-0: 01:33:28 ERROR juju.worker.meterstatus error running "meter-status-changed": charm missing from disk
unit-postgresql-0: 01:34:15 ERROR unit.postgresql/0.juju-log Unable to get the state of the cluster
Traceback (most recent call last):
  File "/var/lib/juju/agents/unit-postgresql-0/charm/venv/lib/python3.10/site-packages/urllib3/connection.py", line 198, in _new_conn
    sock = connection.create_connection(
  File "/var/lib/juju/agents/unit-postgresql-0/charm/venv/lib/python3.10/site-packages/urllib3/util/connection.py", line 85, in create_connection
    raise err
  File "/var/lib/juju/agents/unit-postgresql-0/charm/venv/lib/python3.10/site-packages/urllib3/util/connection.py", line 73, in create_connection
    sock.connect(sa)
ConnectionRefusedError: [Errno 111] Connection refused

The above exception was the direct cause of the following exception:

Traceback (most recent call last):
  File "/var/lib/juju/agents/unit-postgresql-0/charm/venv/lib/python3.10/site-packages/urllib3/connectionpool.py", line 787, in urlopen
    response = self._make_request(
  File "/var/lib/juju/agents/unit-postgresql-0/charm/venv/lib/python3.10/site-packages/urllib3/connectionpool.py", line 493, in _make_request
    conn.request(
  File "/var/lib/juju/agents/unit-postgresql-0/charm/venv/lib/python3.10/site-packages/urllib3/connection.py", line 445, in request
    self.endheaders()
  File "/usr/lib/python3.10/http/client.py", line 1278, in endheaders
    self._send_output(message_body, encode_chunked=encode_chunked)
  File "/usr/lib/python3.10/http/client.py", line 1038, in _send_output
    self.send(msg)
  File "/usr/lib/python3.10/http/client.py", line 976, in send
    self.connect()
  File "/var/lib/juju/agents/unit-postgresql-0/charm/venv/lib/python3.10/site-packages/urllib3/connection.py", line 276, in connect
    self.sock = self._new_conn()
  File "/var/lib/juju/agents/unit-postgresql-0/charm/venv/lib/python3.10/site-packages/urllib3/connection.py", line 213, in _new_conn
    raise NewConnectionError(
urllib3.exceptions.NewConnectionError: <urllib3.connection.HTTPConnection object at 0x7fe0e89a91e0>: Failed to establish a new connection: [Errno 111] Connection refused

The above exception was the direct cause of the following exception:

Traceback (most recent call last):
  File "/var/lib/juju/agents/unit-postgresql-0/charm/venv/lib/python3.10/site-packages/requests/adapters.py", line 667, in send
    resp = conn.urlopen(
  File "/var/lib/juju/agents/unit-postgresql-0/charm/venv/lib/python3.10/site-packages/urllib3/connectionpool.py", line 841, in urlopen
    retries = retries.increment(
  File "/var/lib/juju/agents/unit-postgresql-0/charm/venv/lib/python3.10/site-packages/urllib3/util/retry.py", line 519, in increment
    raise MaxRetryError(_pool, url, reason) from reason  # type: ignore[arg-type]
urllib3.exceptions.MaxRetryError: HTTPConnectionPool(host='10.173.132.229', port=8008): Max retries exceeded with url: /cluster (Caused by NewConnectionError('<urllib3.connection.HTTPConnection object at 0x7fe0e89a91e0>: Failed to establish a new connection: [Errno 111] Connection refused'))

During handling of the above exception, another exception occurred:

Traceback (most recent call last):
  File "/var/lib/juju/agents/unit-postgresql-0/charm/src/cluster.py", line 531, in are_replicas_up
    response = requests.get(
  File "/var/lib/juju/agents/unit-postgresql-0/charm/venv/lib/python3.10/site-packages/requests/api.py", line 73, in get
    return request("get", url, params=params, **kwargs)
  File "/var/lib/juju/agents/unit-postgresql-0/charm/venv/lib/python3.10/site-packages/requests/api.py", line 59, in request
    return session.request(method=method, url=url, **kwargs)
  File "/var/lib/juju/agents/unit-postgresql-0/charm/venv/lib/python3.10/site-packages/requests/sessions.py", line 589, in request
    resp = self.send(prep, **send_kwargs)
  File "/var/lib/juju/agents/unit-postgresql-0/charm/venv/lib/python3.10/site-packages/requests/sessions.py", line 703, in send
    r = adapter.send(request, **kwargs)
  File "/var/lib/juju/agents/unit-postgresql-0/charm/venv/lib/python3.10/site-packages/requests/adapters.py", line 700, in send
    raise ConnectionError(e, request=request)
requests.exceptions.ConnectionError: HTTPConnectionPool(host='10.173.132.229', port=8008): Max retries exceeded with url: /cluster (Caused by NewConnectionError('<urllib3.connection.HTTPConnection object at 0x7fe0e89a91e0>: Failed to establish a new connection: [Errno 111] Connection refused'))
unit-pgbouncer-0: 01:40:05 ERROR juju.worker.meterstatus error running "meter-status-changed": exit status 1
machine-3: 01:43:01 ERROR juju.worker.dependency "lxd-container-provisioner" manifold worker returned unexpected error: container types not yet available
machine-3: 01:43:01 ERROR juju.worker.dependency "kvm-container-provisioner" manifold worker returned unexpected error: container types not yet available
unit-postgresql-test-app-1: 01:43:01 ERROR juju.worker.meterstatus error running "meter-status-changed": charm missing from disk
unit-pgbouncer-1: 01:43:03 ERROR juju.worker.meterstatus error running "meter-status-changed": charm missing from disk
machine-4: 01:45:45 ERROR juju.worker.dependency "kvm-container-provisioner" manifold worker returned unexpected error: container types not yet available
machine-4: 01:45:45 ERROR juju.worker.dependency "lxd-container-provisioner" manifold worker returned unexpected error: container types not yet available
unit-another-application-0: 01:45:46 ERROR juju.worker.meterstatus error running "meter-status-changed": charm missing from disk
machine-6: 01:48:41 ERROR juju.worker.dependency "lxd-container-provisioner" manifold worker returned unexpected error: container types not yet available
machine-6: 01:48:41 ERROR juju.worker.dependency "kvm-container-provisioner" manifold worker returned unexpected error: container types not yet available
unit-another-postgresql-1: 01:48:42 ERROR juju.worker.meterstatus error running "meter-status-changed": charm missing from disk
machine-5: 01:48:42 ERROR juju.worker.dependency "lxd-container-provisioner" manifold worker returned unexpected error: container types not yet available
machine-5: 01:48:42 ERROR juju.worker.dependency "kvm-container-provisioner" manifold worker returned unexpected error: container types not yet available
unit-another-postgresql-0: 01:48:42 ERROR juju.worker.meterstatus error running "meter-status-changed": charm missing from disk
unit-another-postgresql-1: 01:49:33 ERROR unit.another-postgresql/1.juju-log Unable to get the state of the cluster
Traceback (most recent call last):
  File "/var/lib/juju/agents/unit-another-postgresql-1/charm/venv/lib/python3.10/site-packages/urllib3/connection.py", line 198, in _new_conn
    sock = connection.create_connection(
  File "/var/lib/juju/agents/unit-another-postgresql-1/charm/venv/lib/python3.10/site-packages/urllib3/util/connection.py", line 85, in create_connection
    raise err
  File "/var/lib/juju/agents/unit-another-postgresql-1/charm/venv/lib/python3.10/site-packages/urllib3/util/connection.py", line 73, in create_connection
    sock.connect(sa)
ConnectionRefusedError: [Errno 111] Connection refused

The above exception was the direct cause of the following exception:

Traceback (most recent call last):
  File "/var/lib/juju/agents/unit-another-postgresql-1/charm/venv/lib/python3.10/site-packages/urllib3/connectionpool.py", line 787, in urlopen
    response = self._make_request(
  File "/var/lib/juju/agents/unit-another-postgresql-1/charm/venv/lib/python3.10/site-packages/urllib3/connectionpool.py", line 493, in _make_request
    conn.request(
  File "/var/lib/juju/agents/unit-another-postgresql-1/charm/venv/lib/python3.10/site-packages/urllib3/connection.py", line 445, in request
    self.endheaders()
  File "/usr/lib/python3.10/http/client.py", line 1278, in endheaders
    self._send_output(message_body, encode_chunked=encode_chunked)
  File "/usr/lib/python3.10/http/client.py", line 1038, in _send_output
    self.send(msg)
  File "/usr/lib/python3.10/http/client.py", line 976, in send
    self.connect()
  File "/var/lib/juju/agents/unit-another-postgresql-1/charm/venv/lib/python3.10/site-packages/urllib3/connection.py", line 276, in connect
    self.sock = self._new_conn()
  File "/var/lib/juju/agents/unit-another-postgresql-1/charm/venv/lib/python3.10/site-packages/urllib3/connection.py", line 213, in _new_conn
    raise NewConnectionError(
urllib3.exceptions.NewConnectionError: <urllib3.connection.HTTPConnection object at 0x7f6756f9d180>: Failed to establish a new connection: [Errno 111] Connection refused

The above exception was the direct cause of the following exception:

Traceback (most recent call last):
  File "/var/lib/juju/agents/unit-another-postgresql-1/charm/venv/lib/python3.10/site-packages/requests/adapters.py", line 667, in send
    resp = conn.urlopen(
  File "/var/lib/juju/agents/unit-another-postgresql-1/charm/venv/lib/python3.10/site-packages/urllib3/connectionpool.py", line 841, in urlopen
    retries = retries.increment(
  File "/var/lib/juju/agents/unit-another-postgresql-1/charm/venv/lib/python3.10/site-packages/urllib3/util/retry.py", line 519, in increment
    raise MaxRetryError(_pool, url, reason) from reason  # type: ignore[arg-type]
urllib3.exceptions.MaxRetryError: HTTPConnectionPool(host='10.173.132.182', port=8008): Max retries exceeded with url: /cluster (Caused by NewConnectionError('<urllib3.connection.HTTPConnection object at 0x7f6756f9d180>: Failed to establish a new connection: [Errno 111] Connection refused'))

During handling of the above exception, another exception occurred:

Traceback (most recent call last):
  File "/var/lib/juju/agents/unit-another-postgresql-1/charm/src/cluster.py", line 531, in are_replicas_up
    response = requests.get(
  File "/var/lib/juju/agents/unit-another-postgresql-1/charm/venv/lib/python3.10/site-packages/requests/api.py", line 73, in get
    return request("get", url, params=params, **kwargs)
  File "/var/lib/juju/agents/unit-another-postgresql-1/charm/venv/lib/python3.10/site-packages/requests/api.py", line 59, in request
    return session.request(method=method, url=url, **kwargs)
  File "/var/lib/juju/agents/unit-another-postgresql-1/charm/venv/lib/python3.10/site-packages/requests/sessions.py", line 589, in request
    resp = self.send(prep, **send_kwargs)
  File "/var/lib/juju/agents/unit-another-postgresql-1/charm/venv/lib/python3.10/site-packages/requests/sessions.py", line 703, in send
    r = adapter.send(request, **kwargs)
  File "/var/lib/juju/agents/unit-another-postgresql-1/charm/venv/lib/python3.10/site-packages/requests/adapters.py", line 700, in send
    raise ConnectionError(e, request=request)
requests.exceptions.ConnectionError: HTTPConnectionPool(host='10.173.132.182', port=8008): Max retries exceeded with url: /cluster (Caused by NewConnectionError('<urllib3.connection.HTTPConnection object at 0x7f6756f9d180>: Failed to establish a new connection: [Errno 111] Connection refused'))
unit-pgbouncer-2: 01:55:17 ERROR juju.worker.meterstatus error running "meter-status-changed": charm missing from disk
unit-pgbouncer-3: 01:55:18 ERROR juju.worker.meterstatus error running "meter-status-changed": charm missing from disk
unit-another-pgbouncer-0: 01:55:19 ERROR juju.worker.meterstatus error running "meter-status-changed": charm missing from disk
unit-another-pgbouncer-1: 01:55:20 ERROR juju.worker.meterstatus error running "meter-status-changed": exit status 1
unit-pgbouncer-4: 01:57:12 ERROR juju.worker.meterstatus error running "meter-status-changed": charm missing from disk
unit-pgbouncer-5: 01:57:14 ERROR juju.worker.meterstatus error running "meter-status-changed": charm missing from disk
unit-another-pgbouncer-3: 01:57:14 ERROR juju.worker.meterstatus error running "meter-status-changed": charm missing from disk
unit-another-pgbouncer-2: 01:57:14 ERROR juju.worker.meterstatus error running "meter-status-changed": charm missing from disk
machine-7: 02:02:21 ERROR juju.worker.dependency "kvm-container-provisioner" manifold worker returned unexpected error: container types not yet available
machine-7: 02:02:21 ERROR juju.worker.dependency "lxd-container-provisioner" manifold worker returned unexpected error: container types not yet available
unit-postgresql-test-app-2: 02:02:21 ERROR juju.worker.meterstatus error running "meter-status-changed": charm missing from disk
unit-pgbouncer-9: 02:02:24 ERROR juju.worker.meterstatus error running "meter-status-changed": exit status 1
unit-another-pgbouncer-9: 02:02:24 ERROR juju.worker.meterstatus error running "meter-status-changed": exit status 1

[32mINFO    [0m pytest_operator.plugin:plugin.py:1017 Forgetting model main...