[32mINFO    [0m root:helpers.py:96 (0, '{"pgbouncer/5":{"workload-version":"1.21.0","machine":"3","opened-ports":null,"public-address":"10.248.112.192","charm":"local:jammy/pgbouncer-0","leader":true,"life":"alive","relation-info":[{"relation-id":6,"endpoint":"backend-database","related-endpoint":"database","application-data":{"data":"{\\"database\\": \\"pgbouncer\\", \\"extra-user-roles\\": \\"SUPERUSER\\", \\"requested-secrets\\": \\"[\\\\\\"username\\\\\\", \\\\\\"password\\\\\\", \\\\\\"tls\\\\\\", \\\\\\"tls-ca\\\\\\", \\\\\\"uris\\\\\\"]\\"}","database":"pgbouncer","endpoints":"10.248.112.233:5432","read-only-endpoints":"10.248.112.92:5432","secret-tls":"secret://0ce3944b-5835-4174-887b-f786206627cf/ct6h93s84lmhjq61e8tg","secret-user":"secret://0ce3944b-5835-4174-887b-f786206627cf/ct6h93s84lmhjq61e8t0","version":"14.13"},"local-unit":{"in-scope":false,"data":null},"related-units":{"postgresql/0":{"in-scope":true,"data":{"egress-subnets":"10.248.112.233/32","ingress-address":"10.248.112.233","private-address":"10.248.112.233"}},"postgresql/1":{"in-scope":true,"data":{"egress-subnets":"10.248.112.92/32","ingress-address":"10.248.112.92","private-address":"10.248.112.92"}}}},{"relation-id":17,"endpoint":"database","related-endpoint":"database","application-data":{"database":"postgresql_test_app_database","extra-user-roles":"CREATEDB,CREATEROLE","requested-secrets":"[\\"username\\", \\"password\\", \\"tls\\", \\"tls-ca\\", \\"uris\\"]"},"local-unit":{"in-scope":false,"data":null},"related-units":{"postgresql-test-app/1":{"in-scope":true,"data":{"data":"{\\"database\\": \\"postgresql_test_app_database\\", \\"endpoints\\": \\"localhost:6432\\", \\"secret-user\\": \\"secret://0ce3944b-5835-4174-887b-f786206627cf/ct6hmss84lmhjq61e920\\", \\"subordinated\\": \\"true\\", \\"version\\": \\"14.13\\"}","egress-subnets":"10.248.112.192/32","ingress-address":"10.248.112.192","private-address":"10.248.112.192"}},"postgresql-test-app/2":{"in-scope":true,"data":{"data":"{\\"database\\": \\"postgresql_test_app_database\\", \\"endpoints\\": \\"localhost:6432\\", \\"secret-user\\": \\"secret://0ce3944b-5835-4174-887b-f786206627cf/ct6hmss84lmhjq61e920\\", \\"subordinated\\": \\"true\\", \\"version\\": \\"14.13\\"}","egress-subnets":"10.248.112.193/32","ingress-address":"10.248.112.193","private-address":"10.248.112.193"}}}},{"relation-id":5,"endpoint":"pgb-peers","related-endpoint":"pgb-peers","application-data":{"current_port":"6432","leader_ip":"10.248.112.192","pgb_dbs_config":"{\\"17\\": {\\"name\\": \\"postgresql_test_app_database\\", \\"legacy\\": false}, \\"*\\": {\\"name\\": \\"*\\", \\"auth_dbname\\": \\"postgresql_test_app_database\\"}}","readonly_dbs":"[\\"another_database\\", \\"postgresql_test_app_multiple_database_clusters\\"]"},"local-unit":{"in-scope":true,"data":{"auth_file_set":"true","egress-subnets":"10.248.112.192/32","ingress-address":"10.248.112.192","pgb_dbs":"3f7f43cebb47d7003b9dfaa7213fd98c","private-address":"10.248.112.192"}},"related-units":{"pgbouncer/8":{"in-scope":true,"data":{"auth_file_set":"true","egress-subnets":"10.248.112.193/32","ingress-address":"10.248.112.193","pgb_dbs":"3f7f43cebb47d7003b9dfaa7213fd98c","private-address":"10.248.112.193"}}}},{"relation-id":4,"endpoint":"upgrade","related-endpoint":"upgrade","application-data":{"dependencies":"{\\"charm\\": {\\"dependencies\\": {}, \\"name\\": \\"pgbouncer\\", \\"upgrade_supported\\": \\"\\u003e0\\", \\"version\\": \\"1\\"}, \\"snap\\": {\\"dependencies\\": {}, \\"name\\": \\"charmed-postgresql\\", \\"upgrade_supported\\": \\"^1\\", \\"version\\": \\"1.18.0\\"}}"},"local-unit":{"in-scope":true,"data":{"egress-subnets":"10.248.112.192/32","ingress-address":"10.248.112.192","private-address":"10.248.112.192","state":"idle"}},"related-units":{"pgbouncer/8":{"in-scope":true,"data":{"egress-subnets":"10.248.112.193/32","ingress-address":"10.248.112.193","private-address":"10.248.112.193","state":"idle"}}}}]}}\n', '')
[32mINFO    [0m juju.model:model.py:2972 Waiting for model:
  postgresql-test-app/1 [executing] active: received database credentials of the second database
  postgresql-test-app/2 [executing] active: received database credentials of the second database
  postgresql/0 [executing] active: Primary
  postgresql/1 [executing] active:
[32mINFO    [0m pytest_operator.plugin:plugin.py:903 Model status:

Model  Controller           Cloud/Region         Version  SLA          Timestamp
test   localhost-localhost  localhost/localhost  3.4.6    unsupported  02:38:27Z

App                  Version  Status   Scale  Charm                Channel      Rev  Exposed  Message
another-application           active       1  postgresql-test-app  latest/edge  293  no       
another-pgbouncer    1.21.0   active       2  pgbouncer                           1  no       
another-postgresql   14.13    active       2  postgresql           14/edge      530  no       
pgbouncer                     unknown      0  pgbouncer                           0  no       
postgresql           14.13    active       2  postgresql           14/edge      530  no       
postgresql-test-app           active       2  postgresql-test-app  latest/edge  293  no       

Unit                    Workload  Agent  Machine  Public address  Ports     Message
another-application/0*  active    idle   4        10.248.112.66             
another-postgresql/0    active    idle   5        10.248.112.73   5432/tcp  
another-postgresql/1*   active    idle   6        10.248.112.80   5432/tcp  Primary
postgresql-test-app/1*  active    idle   3        10.248.112.192            
  another-pgbouncer/2*  active    idle            10.248.112.192            
postgresql-test-app/2   active    idle   7        10.248.112.193            
  another-pgbouncer/9   active    idle            10.248.112.193            
postgresql/0*           active    idle   0        10.248.112.233  5432/tcp  Primary
postgresql/1            active    idle   1        10.248.112.92   5432/tcp  

Machine  State    Address         Inst id        Base          AZ  Message
0        started  10.248.112.233  juju-6627cf-0  ubuntu@22.04      Running
1        started  10.248.112.92   juju-6627cf-1  ubuntu@22.04      Running
3        started  10.248.112.192  juju-6627cf-3  ubuntu@22.04      Running
4        started  10.248.112.66   juju-6627cf-4  ubuntu@22.04      Running
5        started  10.248.112.73   juju-6627cf-5  ubuntu@22.04      Running
6        started  10.248.112.80   juju-6627cf-6  ubuntu@22.04      Running
7        started  10.248.112.193  juju-6627cf-7  ubuntu@22.04      Running

[32mINFO    [0m pytest_operator.plugin:plugin.py:909 Juju error logs:

machine-2: 01:51:10 ERROR juju.worker.dependency "kvm-container-provisioner" manifold worker returned unexpected error: container types not yet available
machine-2: 01:51:10 ERROR juju.worker.dependency "lxd-container-provisioner" manifold worker returned unexpected error: container types not yet available
unit-postgresql-test-app-0: 01:51:10 ERROR juju.worker.meterstatus error running "meter-status-changed": charm missing from disk
machine-0: 01:51:13 ERROR juju.worker.dependency "lxd-container-provisioner" manifold worker returned unexpected error: container types not yet available
machine-0: 01:51:13 ERROR juju.worker.dependency "kvm-container-provisioner" manifold worker returned unexpected error: container types not yet available
unit-postgresql-0: 01:51:13 ERROR juju.worker.meterstatus error running "meter-status-changed": charm missing from disk
machine-1: 01:51:56 ERROR juju.worker.dependency "kvm-container-provisioner" manifold worker returned unexpected error: container types not yet available
machine-1: 01:51:56 ERROR juju.worker.dependency "lxd-container-provisioner" manifold worker returned unexpected error: container types not yet available
unit-postgresql-1: 01:51:56 ERROR juju.worker.meterstatus error running "meter-status-changed": charm missing from disk
unit-postgresql-0: 01:52:48 ERROR unit.postgresql/0.juju-log Unable to get the state of the cluster
Traceback (most recent call last):
  File "/var/lib/juju/agents/unit-postgresql-0/charm/venv/urllib3/connection.py", line 199, in _new_conn
    sock = connection.create_connection(
  File "/var/lib/juju/agents/unit-postgresql-0/charm/venv/urllib3/util/connection.py", line 85, in create_connection
    raise err
  File "/var/lib/juju/agents/unit-postgresql-0/charm/venv/urllib3/util/connection.py", line 73, in create_connection
    sock.connect(sa)
ConnectionRefusedError: [Errno 111] Connection refused

The above exception was the direct cause of the following exception:

Traceback (most recent call last):
  File "/var/lib/juju/agents/unit-postgresql-0/charm/venv/urllib3/connectionpool.py", line 789, in urlopen
    response = self._make_request(
  File "/var/lib/juju/agents/unit-postgresql-0/charm/venv/urllib3/connectionpool.py", line 495, in _make_request
    conn.request(
  File "/var/lib/juju/agents/unit-postgresql-0/charm/venv/urllib3/connection.py", line 441, in request
    self.endheaders()
  File "/usr/lib/python3.10/http/client.py", line 1278, in endheaders
    self._send_output(message_body, encode_chunked=encode_chunked)
  File "/usr/lib/python3.10/http/client.py", line 1038, in _send_output
    self.send(msg)
  File "/usr/lib/python3.10/http/client.py", line 976, in send
    self.connect()
  File "/var/lib/juju/agents/unit-postgresql-0/charm/venv/urllib3/connection.py", line 279, in connect
    self.sock = self._new_conn()
  File "/var/lib/juju/agents/unit-postgresql-0/charm/venv/urllib3/connection.py", line 214, in _new_conn
    raise NewConnectionError(
urllib3.exceptions.NewConnectionError: <urllib3.connection.HTTPConnection object at 0x7508559ccd90>: Failed to establish a new connection: [Errno 111] Connection refused

The above exception was the direct cause of the following exception:

Traceback (most recent call last):
  File "/var/lib/juju/agents/unit-postgresql-0/charm/venv/requests/adapters.py", line 667, in send
    resp = conn.urlopen(
  File "/var/lib/juju/agents/unit-postgresql-0/charm/venv/urllib3/connectionpool.py", line 843, in urlopen
    retries = retries.increment(
  File "/var/lib/juju/agents/unit-postgresql-0/charm/venv/urllib3/util/retry.py", line 519, in increment
    raise MaxRetryError(_pool, url, reason) from reason  # type: ignore[arg-type]
urllib3.exceptions.MaxRetryError: HTTPConnectionPool(host='10.248.112.233', port=8008): Max retries exceeded with url: /cluster (Caused by NewConnectionError('<urllib3.connection.HTTPConnection object at 0x7508559ccd90>: Failed to establish a new connection: [Errno 111] Connection refused'))

During handling of the above exception, another exception occurred:

Traceback (most recent call last):
  File "/var/lib/juju/agents/unit-postgresql-0/charm/src/cluster.py", line 531, in are_replicas_up
    response = requests.get(
  File "/var/lib/juju/agents/unit-postgresql-0/charm/venv/requests/api.py", line 73, in get
    return request("get", url, params=params, **kwargs)
  File "/var/lib/juju/agents/unit-postgresql-0/charm/venv/requests/api.py", line 59, in request
    return session.request(method=method, url=url, **kwargs)
  File "/var/lib/juju/agents/unit-postgresql-0/charm/venv/requests/sessions.py", line 589, in request
    resp = self.send(prep, **send_kwargs)
  File "/var/lib/juju/agents/unit-postgresql-0/charm/venv/requests/sessions.py", line 703, in send
    r = adapter.send(request, **kwargs)
  File "/var/lib/juju/agents/unit-postgresql-0/charm/venv/requests/adapters.py", line 700, in send
    raise ConnectionError(e, request=request)
requests.exceptions.ConnectionError: HTTPConnectionPool(host='10.248.112.233', port=8008): Max retries exceeded with url: /cluster (Caused by NewConnectionError('<urllib3.connection.HTTPConnection object at 0x7508559ccd90>: Failed to establish a new connection: [Errno 111] Connection refused'))
unit-pgbouncer-0: 01:57:43 ERROR juju.worker.meterstatus error running "meter-status-changed": exit status 1
machine-3: 02:07:02 ERROR juju.worker.dependency "lxd-container-provisioner" manifold worker returned unexpected error: container types not yet available
machine-3: 02:07:02 ERROR juju.worker.dependency "kvm-container-provisioner" manifold worker returned unexpected error: container types not yet available
unit-postgresql-test-app-1: 02:07:02 ERROR juju.worker.meterstatus error running "meter-status-changed": charm missing from disk
unit-pgbouncer-1: 02:07:08 ERROR juju.worker.meterstatus error running "meter-status-changed": exit status 1
machine-4: 02:11:47 ERROR juju.worker.dependency "lxd-container-provisioner" manifold worker returned unexpected error: container types not yet available
machine-4: 02:11:47 ERROR juju.worker.dependency "kvm-container-provisioner" manifold worker returned unexpected error: container types not yet available
unit-another-application-0: 02:11:48 ERROR juju.worker.meterstatus error running "meter-status-changed": charm missing from disk
machine-6: 02:15:16 ERROR juju.worker.dependency "lxd-container-provisioner" manifold worker returned unexpected error: container types not yet available
machine-6: 02:15:16 ERROR juju.worker.dependency "kvm-container-provisioner" manifold worker returned unexpected error: container types not yet available
unit-another-postgresql-1: 02:15:16 ERROR juju.worker.meterstatus error running "meter-status-changed": charm missing from disk
machine-5: 02:15:45 ERROR juju.worker.dependency "kvm-container-provisioner" manifold worker returned unexpected error: container types not yet available
machine-5: 02:15:45 ERROR juju.worker.dependency "lxd-container-provisioner" manifold worker returned unexpected error: container types not yet available
unit-another-postgresql-0: 02:15:45 ERROR juju.worker.meterstatus error running "meter-status-changed": charm missing from disk
unit-another-postgresql-1: 02:19:23 ERROR unit.another-postgresql/1.juju-log Unable to get the state of the cluster
Traceback (most recent call last):
  File "/var/lib/juju/agents/unit-another-postgresql-1/charm/venv/urllib3/connection.py", line 199, in _new_conn
    sock = connection.create_connection(
  File "/var/lib/juju/agents/unit-another-postgresql-1/charm/venv/urllib3/util/connection.py", line 85, in create_connection
    raise err
  File "/var/lib/juju/agents/unit-another-postgresql-1/charm/venv/urllib3/util/connection.py", line 73, in create_connection
    sock.connect(sa)
ConnectionRefusedError: [Errno 111] Connection refused

The above exception was the direct cause of the following exception:

Traceback (most recent call last):
  File "/var/lib/juju/agents/unit-another-postgresql-1/charm/venv/urllib3/connectionpool.py", line 789, in urlopen
    response = self._make_request(
  File "/var/lib/juju/agents/unit-another-postgresql-1/charm/venv/urllib3/connectionpool.py", line 495, in _make_request
    conn.request(
  File "/var/lib/juju/agents/unit-another-postgresql-1/charm/venv/urllib3/connection.py", line 441, in request
    self.endheaders()
  File "/usr/lib/python3.10/http/client.py", line 1278, in endheaders
    self._send_output(message_body, encode_chunked=encode_chunked)
  File "/usr/lib/python3.10/http/client.py", line 1038, in _send_output
    self.send(msg)
  File "/usr/lib/python3.10/http/client.py", line 976, in send
    self.connect()
  File "/var/lib/juju/agents/unit-another-postgresql-1/charm/venv/urllib3/connection.py", line 279, in connect
    self.sock = self._new_conn()
  File "/var/lib/juju/agents/unit-another-postgresql-1/charm/venv/urllib3/connection.py", line 214, in _new_conn
    raise NewConnectionError(
urllib3.exceptions.NewConnectionError: <urllib3.connection.HTTPConnection object at 0x7196481e0d90>: Failed to establish a new connection: [Errno 111] Connection refused

The above exception was the direct cause of the following exception:

Traceback (most recent call last):
  File "/var/lib/juju/agents/unit-another-postgresql-1/charm/venv/requests/adapters.py", line 667, in send
    resp = conn.urlopen(
  File "/var/lib/juju/agents/unit-another-postgresql-1/charm/venv/urllib3/connectionpool.py", line 843, in urlopen
    retries = retries.increment(
  File "/var/lib/juju/agents/unit-another-postgresql-1/charm/venv/urllib3/util/retry.py", line 519, in increment
    raise MaxRetryError(_pool, url, reason) from reason  # type: ignore[arg-type]
urllib3.exceptions.MaxRetryError: HTTPConnectionPool(host='10.248.112.80', port=8008): Max retries exceeded with url: /cluster (Caused by NewConnectionError('<urllib3.connection.HTTPConnection object at 0x7196481e0d90>: Failed to establish a new connection: [Errno 111] Connection refused'))

During handling of the above exception, another exception occurred:

Traceback (most recent call last):
  File "/var/lib/juju/agents/unit-another-postgresql-1/charm/src/cluster.py", line 531, in are_replicas_up
    response = requests.get(
  File "/var/lib/juju/agents/unit-another-postgresql-1/charm/venv/requests/api.py", line 73, in get
    return request("get", url, params=params, **kwargs)
  File "/var/lib/juju/agents/unit-another-postgresql-1/charm/venv/requests/api.py", line 59, in request
    return session.request(method=method, url=url, **kwargs)
  File "/var/lib/juju/agents/unit-another-postgresql-1/charm/venv/requests/sessions.py", line 589, in request
    resp = self.send(prep, **send_kwargs)
  File "/var/lib/juju/agents/unit-another-postgresql-1/charm/venv/requests/sessions.py", line 703, in send
    r = adapter.send(request, **kwargs)
  File "/var/lib/juju/agents/unit-another-postgresql-1/charm/venv/requests/adapters.py", line 700, in send
    raise ConnectionError(e, request=request)
requests.exceptions.ConnectionError: HTTPConnectionPool(host='10.248.112.80', port=8008): Max retries exceeded with url: /cluster (Caused by NewConnectionError('<urllib3.connection.HTTPConnection object at 0x7196481e0d90>: Failed to establish a new connection: [Errno 111] Connection refused'))
unit-pgbouncer-2: 02:25:32 ERROR juju.worker.meterstatus error running "meter-status-changed": exit status 1
unit-another-pgbouncer-0: 02:25:33 ERROR juju.worker.meterstatus error running "meter-status-changed": exit status 1
unit-pgbouncer-3: 02:25:33 ERROR juju.worker.meterstatus error running "meter-status-changed": exit status 1
unit-another-pgbouncer-1: 02:25:33 ERROR juju.worker.meterstatus error running "meter-status-changed": exit status 1
unit-pgbouncer-5: 02:28:01 ERROR juju.worker.meterstatus error running "meter-status-changed": charm missing from disk
unit-pgbouncer-4: 02:28:01 ERROR juju.worker.meterstatus error running "meter-status-changed": charm missing from disk
unit-another-pgbouncer-2: 02:28:02 ERROR juju.worker.meterstatus error running "meter-status-changed": charm missing from disk
unit-another-pgbouncer-3: 02:28:02 ERROR juju.worker.meterstatus error running "meter-status-changed": charm missing from disk
machine-7: 02:35:19 ERROR juju.worker.dependency "lxd-container-provisioner" manifold worker returned unexpected error: container types not yet available
machine-7: 02:35:19 ERROR juju.worker.dependency "kvm-container-provisioner" manifold worker returned unexpected error: container types not yet available
unit-postgresql-test-app-2: 02:35:19 ERROR juju.worker.meterstatus error running "meter-status-changed": charm missing from disk
unit-another-pgbouncer-9: 02:35:26 ERROR juju.worker.meterstatus error running "meter-status-changed": charm missing from disk
unit-pgbouncer-8: 02:35:26 ERROR juju.worker.meterstatus error running "meter-status-changed": charm missing from disk
machine-3: 02:38:03 ERROR juju.api.watcher error trying to stop watcher: websocket: close sent

[32mINFO    [0m pytest_operator.plugin:plugin.py:991 Forgetting model main...